Workbook

Sheet بيانات
A1: نظام إدارة اشتراكات — نادي RCS
A2: رقم الملف | B2: اللقب | C2: الاسم | D2: تاريخ الميلاد | E2: الجنس | F2: العمر | G2: فصيلة الدم | H2: نوع الاشتراك | I2: تاريخ آخر دفعة | J2: تاريخ انتهاء الاشتراك | K2: حالة الدفع | L2: رسوم الاشتراك | M2: مصاريف التأمين | N2: حقوق المركب | O2: المبلغ الإجمالي | P2: حالة التجديد | Q2: أيام السباحة | R2: التوقيت | S2: عدد أشهر الاشتراك | T2: البادئة
A3: =IF(B3="","",IF(T3="?","⚠️ نوع غير معرف",T3&TEXT(COUNTIFS($T$3:T3,T3),"000"))) -> RCS001 | B3: بورقعة | C3: محمد الأمين | D3: 41766 | E3: ذكر | F3: =IF(D3="","",DATEDIF(D3,TODAY(),"Y")) -> 12 | H3: / | I3: 46190 | J3: =IF(I3="","",I3+30) -> 46220 | K3: مدفوع | L3: =IF(OR(K3="لم يدفع",B3=""),"",IF(K3="تأمين فقط",0,IF(K3="اشتراك 300",300,IF(F3<14,IFERROR(VLOOKUP(SUBSTITUTE(SUBSTITUTE(H3,"~","~~"),"*","~*"),إعدادات_الأنواع!$A$4:$D$40,3,FALSE()),0),IFERROR(VLOOKUP(SUBSTITUTE(SUBSTITUTE(H3,"~","~~"),"*","~*"),إعدادات_الأنواع!$A$4:$D$40,4,FALSE()),0))))) -> 1300 | M3: =IF(OR(K3="لم يدفع",B3=""),"",IFERROR(VLOOKUP(SUBSTITUTE(SUBSTITUTE(H3,"~","~~"),"*","~*"),إعدادات_الأنواع!$A$4:$E$40,5,FALSE()),0)) -> 500 | N3: =IF(OR(K3="لم يدفع",K3="تأمين فقط",K3="اشتراك 300",B3=""),"",IFERROR(VLOOKUP(SUBSTITUTE(SUBSTITUTE(H3,"~","~~"),"*","~*"),إعدادات_الأنواع!$A$4:$F$40,6,FALSE()),0)) -> 1000 | O3: =IF(K3="لم يدفع","",IF(L3="","",IF(N3="",L3+M3,L3+M3))) -> 1800 | P3: =IF(B3="","",IF(K3="لم يدفع","🔒 مجمدة",IF(J3="","",IF(J3<TODAY(),"⛔ منتهي - يتطلب تجديد",IF(J3-5<=TODAY(),"⚠️ قريب الانتهاء","✅ ساري"))))) -> ⚠️ قريب الانتهاء | Q3: الأحد والأربعاء | R3: 10:00-11:00 | S3: =IF(B3="","",COUNTA(التجديد!E3:E3)) -> 0 | T3: =IF(B3="","",IFERROR(VLOOKUP(SUBSTITUTE(SUBSTITUTE(H3,"~","~~"),"*","~*"),إعدادات_الأنواع!$A$4:$B$40,2,FALSE()),"?")) -> RCS
A4: =IF(B4="","",IF(T4="?","⚠️ نوع غير معرف",T4&TEXT(COUNTIFS($T$3:T4,T4),"000"))) -> RCS002 | B4: براهمي | C4: ياسين صلاح الدين | D4: 41925 | E4: ذكر | F4: =IF(D4="","",DATEDIF(D4,TODAY(),"Y")) -> 11 | G4: AB+ | H4: / | I4: 46190 | J4: =IF(I4="","",I4+30) -> 46220 | K4: مدفوع | L4: =IF(OR(K4="لم يدفع",B4=""),"",IF(K4="تأمين فقط",0,IF(K4="اشتراك 300",300,IF(F4<14,IFERROR(VLOOKUP(SUBSTITUTE(SUBSTITUTE(H4,"~","~~"),"*","~*"),إعدادات_الأنواع!$A$4:$D$40,3,FALSE()),0),IFERROR(VLOOKUP(SUBSTITUTE(SUBSTITUTE(H4,"~","~~"),"*","~*"),إعدادات_الأنواع!$A$4:$D$40,4,FALSE()),0))))) -> 1300 | M4: =IF(OR(K4="لم يدفع",B4=""),"",IFERROR(VLOOKUP(SUBSTITUTE(SUBSTITUTE(H4,"~","~~"),"*","~*"),إعدادات_الأنواع!$A$4:$E$40,5,FALSE()),0)) -> 500 | N4: =IF(OR(K4="لم يدفع",K4="تأمين فقط",K4="اشتراك 300",B4=""),"",IFERROR(VLOOKUP(SUBSTITUTE(SUBSTITUTE(H4,"~","~~"),"*","~*"),إعدادات_الأنواع!$A$4:$F$40,6,FALSE()),0)) -> 1000 | O4: =IF(K4="لم يدفع","",IF(L4="","",IF(N4="",L4+M4,L4+M4))) -> 1800 | P4: =IF(B4="","",IF(K4="لم يدفع","🔒 مجمدة",IF(J4="","",IF(J4<TODAY(),"⛔ منتهي - يتطلب تجديد",IF(J4-5<=TODAY(),"⚠️ قريب الانتهاء","✅ ساري"))))) -> ⚠️ قريب الانتهاء | Q4: الأحد والأربعاء | R4: 10:00-11:00 | S4: =IF(B4="","",COUNTA(التجديد!E4:E4)) -> 0 | T4: =IF(B4="","",IFERROR(VLOOKUP(SUBSTITUTE(SUBSTITUTE(H4,"~","~~"),"*","~*"),إعدادات_الأنواع!$A$4:$B$40,2,FALSE()),"?")) -> RCS
A5: =IF(B5="","",IF(T5="?","⚠️ نوع غير معرف",T5&TEXT(COUNTIFS($T$3:T5,T5),"000"))) -> RCS003 | B5: براهمي | C5: فؤاد عبد القادر | D5: 40915 | E5: ذكر | F5: =IF(D5="","",DATEDIF(D5,TODAY(),"Y")) -> 14 | G5: A+ | H5: / | I5: 46190 | J5: =IF(I5="","",I5+30) -> 46220 | K5: مدفوع | L5: =IF(OR(K5="لم يدفع",B5=""),"",IF(K5="تأمين فقط",0,IF(K5="اشتراك 300",300,IF(F5<14,IFERROR(VLOOKUP(SUBSTITUTE(SUBSTITUTE(H5,"~","~~"),"*","~*"),إعدادات_الأنواع!$A$4:$D$40,3,FALSE()),0),IFERROR(VLOOKUP(SUBSTITUTE(SUBSTITUTE(H5,"~","~~"),"*","~*"),إعدادات_الأنواع!$A$4:$D$40,4,FALSE()),0))))) -> 1500 | M5: =IF(OR(K5="لم يدفع",B5=""),"",IFERROR(VLOOKUP(SUBSTITUTE(SUBSTITUTE(H5,"~","~~"),"*","~*"),إعدادات_الأنواع!$A$4:$E$40,5,FALSE()),0)) -> 500 | N5: =IF(OR(K5="لم يدفع",K5="تأمين فقط",K5="اشتراك 300",B5=""),"",IFERROR(VLOOKUP(SUBSTITUTE(SUBSTITUTE(H5,"~","~~"),"*","~*"),إعدادات_الأنواع!$A$4:$F$40,6,FALSE()),0)) -> 1000 | O5: =IF(K5="لم يدفع","",IF(L5="","",IF(N5="",L5+M5,L5+M5))) -> 2000 | P5: =IF(B5="","",IF(K5="لم يدفع","🔒 مجمدة",IF(J5="","",IF(J5<TODAY(),"⛔ منتهي - يتطلب تجديد",IF(J5-5<=TODAY(),"⚠️ قريب الانتهاء","✅ ساري"))))) -> ⚠️ قريب الانتهاء | Q5: الأحد والأربعاء | R5: 10:00-11:00 | S5: =IF(B5="","",COUNTA(التجديد!E5:E5)) -> 0 | T5: =IF(B5="","",IFERROR(VLOOKUP(SUBSTITUTE(SUBSTITUTE(H5,"~","~~"),"*","~*"),إعدادات_الأنواع!$A$4:$B$40,2,FALSE()),"?")) -> RCS
A6: =IF(B6="","",IF(T6="?","⚠️ نوع غير معرف",T6&TEXT(COUNTIFS($T$3:T6,T6),"000"))) -> RCS004 | B6: يحياوي | C6: عز الدين عبد القادر | D6: 42864 | E6: ذكر | F6: =IF(D6="","",DATEDIF(D6,TODAY(),"Y")) -> 9 | G6: A+ | H6: / | I6: 46190 | J6: =IF(I6="","",I6+30) -> 46220 | K6: مدفوع | L6: =IF(OR(K6="لم يدفع",B6=""),"",IF(K6="تأمين فقط",0,IF(K6="اشتراك 300",300,IF(F6<14,IFERROR(VLOOKUP(SUBSTITUTE(SUBSTITUTE(H6,"~","~~"),"*","~*"),إعدادات_الأنواع!$A$4:$D$40,3,FALSE()),0),IFERROR(VLOOKUP(SUBSTITUTE(SUBSTITUTE(H6,"~","~~"),"*","~*"),إعدادات_الأنواع!$A$4:$D$40,4,FALSE()),0))))) -> 1300 | M6: =IF(OR(K6="لم يدفع",B6=""),"",IFERROR(VLOOKUP(SUBSTITUTE(SUBSTITUTE(H6,"~","~~"),"*","~*"),إعدادات_الأنواع!$A$4:$E$40,5,FALSE()),0)) -> 500 | N6: =IF(OR(K6="لم يدفع",K6="تأمين فقط",K6="اشتراك 300",B6=""),"",IFERROR(VLOOKUP(SUBSTITUTE(SUBSTITUTE(H6,"~","~~"),"*","~*"),إعدادات_الأنواع!$A$4:$F$40,6,FALSE()),0)) -> 1000 | O6: =IF(K6="لم يدفع","",IF(L6="","",IF(N6="",L6+M6,L6+M6))) -> 1800 | P6: =IF(B6="","",IF(K6="لم يدفع","🔒 مجمدة",IF(J6="","",IF(J6<TODAY(),"⛔ منتهي - يتطلب تجديد",IF(J6-5<=TODAY(),"⚠️ قريب الانتهاء","✅ ساري"))))) -> ⚠️ قريب الانتهاء | Q6: الأحد والأربعاء | R6: 10:00-11:00 | S6: =IF(B6="","",COUNTA(التجديد!E6:E6)) -> 0 | T6: =IF(B6="","",IFERROR(VLOOKUP(SUBSTITUTE(SUBSTITUTE(H6,"~","~~"),"*","~*"),إعدادات_الأنواع!$A$4:$B$40,2,FALSE()),"?")) -> RCS
A7: =IF(B7="","",IF(T7="?","⚠️ نوع غير معرف",T7&TEXT(COUNTIFS($T$3:T7,T7),"000"))) -> RCS005 | B7: غزالي | C7: ياسر | D7: 42727 | E7: ذكر | F7: =IF(D7="","",DATEDIF(D7,TODAY(),"Y")) -> 9 | G7: O- | H7: DJS | I7: 46190 | J7: =IF(I7="","",I7+30) -> 46220 | K7: مدفوع | L7: =IF(OR(K7="لم يدفع",B7=""),"",IF(K7="تأمين فقط",0,IF(K7="اشتراك 300",300,IF(F7<14,IFERROR(VLOOKUP(SUBSTITUTE(SUBSTITUTE(H7,"~","~~"),"*","~*"),إعدادات_الأنواع!$A$4:$D$40,3,FALSE()),0),IFERROR(VLOOKUP(SUBSTITUTE(SUBSTITUTE(H7,"~","~~"),"*","~*"),إعدادات_الأنواع!$A$4:$D$40,4,FALSE()),0))))) -> 300 | M7: =IF(OR(K7="لم يدفع",B7=""),"",IFERROR(VLOOKUP(SUBSTITUTE(SUBSTITUTE(H7,"~","~~"),"*","~*"),إعدادات_الأنواع!$A$4:$E$40,5,FALSE()),0)) -> 500 | N7: =IF(OR(K7="لم يدفع",K7="تأمين فقط",K7="اشتراك 300",B7=""),"",IFERROR(VLOOKUP(SUBSTITUTE(SUBSTITUTE(H7,"~","~~"),"*","~*"),إعدادات_الأنواع!$A$4:$F$40,6,FALSE()),0)) -> 0 | O7: =IF(K7="لم يدفع","",IF(L7="","",IF(N7="",L7+M7,L7+M7))) -> 800 | P7: =IF(B7="","",IF(K7="لم يدفع","🔒 مجمدة",IF(J7="","",IF(J7<TODAY(),"⛔ منتهي - يتطلب تجديد",IF(J7-5<=TODAY(),"⚠️ قريب الانتهاء","✅ ساري"))))) -> ⚠️ قريب الانتهاء | Q7: الأحد والأربعاء | R7: 10:00-11:00 | S7: =IF(B7="","",COUNTA(التجديد!E7:E7)) -> 0 | T7: =IF(B7="","",IFERROR(VLOOKUP(SUBSTITUTE(SUBSTITUTE(H7,"~","~~"),"*","~*"),إعدادات_الأنواع!$A$4:$B$40,2,FALSE()),"?")) -> RCS
A8: =IF(B8="","",IF(T8="?","⚠️ نوع غير معرف",T8&TEXT(COUNTIFS($T$3:T8,T8),"000"))) -> RCS006 | B8: غزالي | C8: آية | D8: 43275 | E8: أنثى | F8: =IF(D8="","",DATEDIF(D8,TODAY(),"Y")) -> 8 | G8: A- | H8: DJS | I8: 46190 | J8: =IF(I8="","",I8+30) -> 46220 | K8: مدفوع | L8: =IF(OR(K8="لم يدفع",B8=""),"",IF(K8="تأمين فقط",0,IF(K8="اشتراك 300",300,IF(F8<14,IFERROR(VLOOKUP(SUBSTITUTE(SUBSTITUTE(H8,"~","~~"),"*","~*"),إعدادات_الأنواع!$A$4:$D$40,3,FALSE()),0),IFERROR(VLOOKUP(SUBSTITUTE(SUBSTITUTE(H8,"~","~~"),"*","~*"),إعدادات_الأنواع!$A$4:$D$40,4,FALSE()),0))))) -> 300 | M8: =IF(OR(K8="لم يدفع",B8=""),"",IFERROR(VLOOKUP(SUBSTITUTE(SUBSTITUTE(H8,"~","~~"),"*","~*"),إعدادات_الأنواع!$A$4:$E$40,5,FALSE()),0)) -> 500 | N8: =IF(OR(K8="لم يدفع",K8="تأمين فقط",K8="اشتراك 300",B8=""),"",IFERROR(VLOOKUP(SUBSTITUTE(SUBSTITUTE(H8,"~","~~"),"*","~*"),إعدادات_الأنواع!$A$4:$F$40,6,FALSE()),0)) -> 0 | O8: =IF(K8="لم يدفع","",IF(L8="","",IF(N8="",L8+M8,L8+M8))) -> 800 | P8: =IF(B8="","",IF(K8="لم يدفع","🔒 مجمدة",IF(J8="","",IF(J8<TODAY(),"⛔ منتهي - يتطلب تجديد",IF(J8-5<=TODAY(),"⚠️ قريب الانتهاء","✅ ساري"))))) -> ⚠️ قريب الانتهاء | Q8: الأحد والأربعاء | R8: 9:00-10:00 | S8: =IF(B8="","",COUNTA(التجديد!E8:E8)) -> 0 | T8: =IF(B8="","",IFERROR(VLOOKUP(SUBSTITUTE(SUBSTITUTE(H8,"~","~~"),"*","~*"),إعدادات_الأنواع!$A$4:$B$40,2,FALSE()),"?")) -> RCS
A9: =IF(B9="","",IF(T9="?","⚠️ نوع غير معرف",T9&TEXT(COUNTIFS($T$3:T9,T9),"000"))) -> RCS007 | B9: علو | C9: عبد الإله | D9: 41323 | E9: ذكر | F9: =IF(D9="","",DATEDIF(D9,TODAY(),"Y")) -> 13 | G9: O+ | H9: / | I9: 46190 | J9: =IF(I9="","",I9+30) -> 46220 | K9: لم يدفع | L9: =IF(OR(K9="لم يدفع",B9=""),"",IF(K9="تأمين فقط",0,IF(K9="اشتراك 300",300,IF(F9<14,IFERROR(VLOOKUP(SUBSTITUTE(SUBSTITUTE(H9,"~","~~"),"*","~*"),إعدادات_الأنواع!$A$4:$D$40,3,FALSE()),0),IFERROR(VLOOKUP(SUBSTITUTE(SUBSTITUTE(H9,"~","~~"),"*","~*"),إعدادات_الأنواع!$A$4:$D$40,4,FALSE()),0))))) | M9: =IF(OR(K9="لم يدفع",B9=""),"",IFERROR(VLOOKUP(SUBSTITUTE(SUBSTITUTE(H9,"~","~~"),"*","~*"),إعدادات_الأنواع!$A$4:$E$40,5,FALSE()),0)) | N9: =IF(OR(K9="لم يدفع",K9="تأمين فقط",K9="اشتراك 300",B9=""),"",IFERROR(VLOOKUP(SUBSTITUTE(SUBSTITUTE(H9,"~","~~"),"*","~*"),إعدادات_الأنواع!$A$4:$F$40,6,FALSE()),0)) | O9: =IF(K9="لم يدفع","",IF(L9="","",IF(N9="",L9+M9,L9+M9))) | P9: =IF(B9="","",IF(K9="لم يدفع","🔒 مجمدة",IF(J9="","",IF(J9<TODAY(),"⛔ منتهي - يتطلب تجديد",IF(J9-5<=TODAY(),"⚠️ قريب الانتهاء","✅ ساري"))))) -> 🔒 مجمدة | Q9: الأحد والأربعاء | R9: 10:00-11:00 | S9: =IF(B9="","",COUNTA(التجديد!E9:E9)) -> 0 | T9: =IF(B9="","",IFERROR(VLOOKUP(SUBSTITUTE(SUBSTITUTE(H9,"~","~~"),"*","~*"),إعدادات_الأنواع!$A$4:$B$40,2,FALSE()),"?")) -> RCS
A10: =IF(B10="","",IF(T10="?","⚠️ نوع غير معرف",T10&TEXT(COUNTIFS($T$3:T10,T10),"000"))) -> RCS008 | B10: علو | C10: صهيب | D10: 43273 | E10: ذكر | F10: =IF(D10="","",DATEDIF(D10,TODAY(),"Y")) -> 8 | G10: O+ | H10: / | I10: 46190 | J10: =IF(I10="","",I10+30) -> 46220 | K10: لم يدفع | L10: =IF(OR(K10="لم يدفع",B10=""),"",IF(K10="تأمين فقط",0,IF(K10="اشتراك 300",300,IF(F10<14,IFERROR(VLOOKUP(SUBSTITUTE(SUBSTITUTE(H10,"~","~~"),"*","~*"),إعدادات_الأنواع!$A$4:$D$40,3,FALSE()),0),IFERROR(VLOOKUP(SUBSTITUTE(SUBSTITUTE(H10,"~","~~"),"*","~*"),إعدادات_الأنواع!$A$4:$D$40,4,FALSE()),0))))) | M10: =IF(OR(K10="لم يدفع",B10=""),"",IFERROR(VLOOKUP(SUBSTITUTE(SUBSTITUTE(H10,"~","~~"),"*","~*"),إعدادات_الأنواع!$A$4:$E$40,5,FALSE()),0)) | N10: =IF(OR(K10="لم يدفع",K10="تأمين فقط",K10="اشتراك 300",B10=""),"",IFERROR(VLOOKUP(SUBSTITUTE(SUBSTITUTE(H10,"~","~~"),"*","~*"),إعدادات_الأنواع!$A$4:$F$40,6,FALSE()),0)) | O10: =IF(K10="لم يدفع","",IF(L10="","",IF(N10="",L10+M10,L10+M10))) | P10: =IF(B10="","",IF(K10="لم يدفع","🔒 مجمدة",IF(J10="","",IF(J10<TODAY(),"⛔ منتهي - يتطلب تجديد",IF(J10-5<=TODAY(),"⚠️ قريب الانتهاء","✅ ساري"))))) -> 🔒 مجمدة | Q10: الأحد والأربعاء | R10: 10:00-11:00 | S10: =IF(B10="","",COUNTA(التجديد!E10:E10)) -> 0 | T10: =IF(B10="","",IFERROR(VLOOKUP(SUBSTITUTE(SUBSTITUTE(H10,"~","~~"),"*","~*"),إعدادات_الأنواع!$A$4:$B$40,2,FALSE()),"?")) -> RCS
A11: =IF(B11="","",IF(T11="?","⚠️ نوع غير معرف",T11&TEXT(COUNTIFS($T$3:T11,T11),"000"))) -> RCS009 | B11: علام | C11: محمد | D11: 42326 | E11: ذكر | F11: =IF(D11="","",DATEDIF(D11,TODAY(),"Y")) -> 10 | H11: / | I11: 46190 | J11: =IF(I11="","",I11+30) -> 46220 | K11: مدفوع | L11: =IF(OR(K11="لم يدفع",B11=""),"",IF(K11="تأمين فقط",0,IF(K11="اشتراك 300",300,IF(F11<14,IFERROR(VLOOKUP(SUBSTITUTE(SUBSTITUTE(H11,"~","~~"),"*","~*"),إعدادات_الأنواع!$A$4:$D$40,3,FALSE()),0),IFERROR(VLOOKUP(SUBSTITUTE(SUBSTITUTE(H11,"~","~~"),"*","~*"),إعدادات_الأنواع!$A$4:$D$40,4,FALSE()),0))))) -> 1300 | M11: =IF(OR(K11="لم يدفع",B11=""),"",IFERROR(VLOOKUP(SUBSTITUTE(SUBSTITUTE(H11,"~","~~"),"*","~*"),إعدادات_الأنواع!$A$4:$E$40,5,FALSE()),0)) -> 500 | N11: =IF(OR(K11="لم يدفع",K11="تأمين فقط",K11="اشتراك 300",B11=""),"",IFERROR(VLOOKUP(SUBSTITUTE(SUBSTITUTE(H11,"~","~~"),"*","~*"),إعدادات_الأنواع!$A$4:$F$40,6,FALSE()),0)) -> 1000 | O11: =IF(K11="لم يدفع","",IF(L11="","",IF(N11="",L11+M11,L11+M11))) -> 1800 | P11: =IF(B11="","",IF(K11="لم يدفع","🔒 مجمدة",IF(J11="","",IF(J11<TODAY(),"⛔ منتهي - يتطلب تجديد",IF(J11-5<=TODAY(),"⚠️ قريب الانتهاء","✅ ساري"))))) -> ⚠️ قريب الانتهاء | Q11: الأحد والأربعاء | R11: 10:00-11:00 | S11: =IF(B11="","",COUNTA(التجديد!E11:E11)) -> 0 | T11: =IF(B11="","",IFERROR(VLOOKUP(SUBSTITUTE(SUBSTITUTE(H11,"~","~~"),"*","~*"),إعدادات_الأنواع!$A$4:$B$40,2,FALSE()),"?")) -> RCS
A12: =IF(B12="","",IF(T12="?","⚠️ نوع غير معرف",T12&TEXT(COUNTIFS($T$3:T12,T12),"000"))) -> RCS010 | B12: علو | C12: ادم ضياء الدين | D12: 41123 | E12: ذكر | F12: =IF(D12="","",DATEDIF(D12,TODAY(),"Y")) -> 13 | H12: / | I12: 46190 | J12: =IF(I12="","",I12+30) -> 46220 | K12: مدفوع | L12: =IF(OR(K12="لم يدفع",B12=""),"",IF(K12="تأمين فقط",0,IF(K12="اشتراك 300",300,IF(F12<14,IFERROR(VLOOKUP(SUBSTITUTE(SUBSTITUTE(H12,"~","~~"),"*","~*"),إعدادات_الأنواع!$A$4:$D$40,3,FALSE()),0),IFERROR(VLOOKUP(SUBSTITUTE(SUBSTITUTE(H12,"~","~~"),"*","~*"),إعدادات_الأنواع!$A$4:$D$40,4,FALSE()),0))))) -> 1300 | M12: =IF(OR(K12="لم يدفع",B12=""),"",IFERROR(VLOOKUP(SUBSTITUTE(SUBSTITUTE(H12,"~","~~"),"*","~*"),إعدادات_الأنواع!$A$4:$E$40,5,FALSE()),0)) -> 500 | N12: =IF(OR(K12="لم يدفع",K12="تأمين فقط",K12="اشتراك 300",B12=""),"",IFERROR(VLOOKUP(SUBSTITUTE(SUBSTITUTE(H12,"~","~~"),"*","~*"),إعدادات_الأنواع!$A$4:$F$40,6,FALSE()),0)) -> 1000 | O12: =IF(K12="لم يدفع","",IF(L12="","",IF(N12="",L12+M12,L12+M12))) -> 1800 | P12: =IF(B12="","",IF(K12="لم يدفع","🔒 مجمدة",IF(J12="","",IF(J12<TODAY(),"⛔ منتهي - يتطلب تجديد",IF(J12-5<=TODAY(),"⚠️ قريب الانتهاء","✅ ساري"))))) -> ⚠️ قريب الانتهاء | Q12: الأحد والأربعاء | R12: 10:00-11:00 | S12: =IF(B12="","",COUNTA(التجديد!E12:E12)) -> 0 | T12: =IF(B12="","",IFERROR(VLOOKUP(SUBSTITUTE(SUBSTITUTE(H12,"~","~~"),"*","~*"),إعدادات_الأنواع!$A$4:$B$40,2,FALSE()),"?")) -> RCS
A13: =IF(B13="","",IF(T13="?","⚠️ نوع غير معرف",T13&TEXT(COUNTIFS($T$3:T13,T13),"000"))) -> RCS011 | B13: بغاديد | C13: احمد عماد الدين | D13: 41578 | E13: ذكر | F13: =IF(D13="","",DATEDIF(D13,TODAY(),"Y")) -> 12 | H13: / | I13: 46194 | J13: =IF(I13="","",I13+30) -> 46224 | K13: مدفوع | L13: =IF(OR(K13="لم يدفع",B13=""),"",IF(K13="تأمين فقط",0,IF(K13="اشتراك 300",300,IF(F13<14,IFERROR(VLOOKUP(SUBSTITUTE(SUBSTITUTE(H13,"~","~~"),"*","~*"),إعدادات_الأنواع!$A$4:$D$40,3,FALSE()),0),IFERROR(VLOOKUP(SUBSTITUTE(SUBSTITUTE(H13,"~","~~"),"*","~*"),إعدادات_الأنواع!$A$4:$D$40,4,FALSE()),0))))) -> 1300 | M13: =IF(OR(K13="لم يدفع",B13=""),"",IFERROR(VLOOKUP(SUBSTITUTE(SUBSTITUTE(H13,"~","~~"),"*","~*"),إعدادات_الأنواع!$A$4:$E$40,5,FALSE()),0)) -> 500 | N13: =IF(OR(K13="لم يدفع",K13="تأمين فقط",K13="اشتراك 300",B13=""),"",IFERROR(VLOOKUP(SUBSTITUTE(SUBSTITUTE(H13,"~","~~"),"*","~*"),إعدادات_الأنواع!$A$4:$F$40,6,FALSE()),0)) -> 1000 | O13: =IF(K13="لم يدفع","",IF(L13="","",IF(N13="",L13+M13,L13+M13))) -> 1800 | P13: =IF(B13="","",IF(K13="لم يدفع","🔒 مجمدة",IF(J13="","",IF(J13<TODAY(),"⛔ منتهي - يتطلب تجديد",IF(J13-5<=TODAY(),"⚠️ قريب الانتهاء","✅ ساري"))))) -> ✅ ساري | Q13: الأحد والأربعاء | R13: 10:00-11:00 | S13: =IF(B13="","",COUNTA(التجديد!E13:E13)) -> 0 | T13: =IF(B13="","",IFERROR(VLOOKUP(SUBSTITUTE(SUBSTITUTE(H13,"~","~~"),"*","~*"),إعدادات_الأنواع!$A$4:$B$40,2,FALSE()),"?")) -> RCS
A14: =IF(B14="","",IF(T14="?","⚠️ نوع غير معرف",T14&TEXT(COUNTIFS($T$3:T14,T14),"000"))) -> RCS012 | B14: هواري | C14: عماد ايمن | D14: 42242 | E14: ذكر | F14: =IF(D14="","",DATEDIF(D14,TODAY(),"Y")) -> 10 | H14: / | I14: 46194 | J14: =IF(I14="","",I14+30) -> 46224 | K14: مدفوع | L14: =IF(OR(K14="لم يدفع",B14=""),"",IF(K14="تأمين فقط",0,IF(K14="اشتراك 300",300,IF(F14<14,IFERROR(VLOOKUP(SUBSTITUTE(SUBSTITUTE(H14,"~","~~"),"*","~*"),إعدادات_الأنواع!$A$4:$D$40,3,FALSE()),0),IFERROR(VLOOKUP(SUBSTITUTE(SUBSTITUTE(H14,"~","~~"),"*","~*"),إعدادات_الأنواع!$A$4:$D$40,4,FALSE()),0))))) -> 1300 | M14: =IF(OR(K14="لم يدفع",B14=""),"",IFERROR(VLOOKUP(SUBSTITUTE(SUBSTITUTE(H14,"~","~~"),"*","~*"),إعدادات_الأنواع!$A$4:$E$40,5,FALSE()),0)) -> 500 | N14: =IF(OR(K14="لم يدفع",K14="تأمين فقط",K14="اشتراك 300",B14=""),"",IFERROR(VLOOKUP(SUBSTITUTE(SUBSTITUTE(H14,"~","~~"),"*","~*"),إعدادات_الأنواع!$A$4:$F$40,6,FALSE()),0)) -> 1000 | O14: =IF(K14="لم يدفع","",IF(L14="","",IF(N14="",L14+M14,L14+M14))) -> 1800 | P14: =IF(B14="","",IF(K14="لم يدفع","🔒 مجمدة",IF(J14="","",IF(J14<TODAY(),"⛔ منتهي - يتطلب تجديد",IF(J14-5<=TODAY(),"⚠️ قريب الانتهاء","✅ ساري"))))) -> ✅ ساري | Q14: الأحد والأربعاء | R14: 10:00-11:00 | S14: =IF(B14="","",COUNTA(التجديد!E14:E14)) -> 0 | T14: =IF(B14="","",IFERROR(VLOOKUP(SUBSTITUTE(SUBSTITUTE(H14,"~","~~"),"*","~*"),إعدادات_الأنواع!$A$4:$B$40,2,FALSE()),"?")) -> RCS
A15: =IF(B15="","",IF(T15="?","⚠️ نوع غير معرف",T15&TEXT(COUNTIFS($T$3:T15,T15),"000"))) -> RCS013 | B15: بن | C15: حشيليف رنيم سجود | D15: 44220 | E15: أنثى | F15: =IF(D15="","",DATEDIF(D15,TODAY(),"Y")) -> 5 | H15: / | I15: 46194 | J15: =IF(I15="","",I15+30) -> 46224 | K15: مدفوع | L15: =IF(OR(K15="لم يدفع",B15=""),"",IF(K15="تأمين فقط",0,IF(K15="اشتراك 300",300,IF(F15<14,IFERROR(VLOOKUP(SUBSTITUTE(SUBSTITUTE(H15,"~","~~"),"*","~*"),إعدادات_الأنواع!$A$4:$D$40,3,FALSE()),0),IFERROR(VLOOKUP(SUBSTITUTE(SUBSTITUTE(H15,"~","~~"),"*","~*"),إعدادات_الأنواع!$A$4:$D$40,4,FALSE()),0))))) -> 1300 | M15: =IF(OR(K15="لم يدفع",B15=""),"",IFERROR(VLOOKUP(SUBSTITUTE(SUBSTITUTE(H15,"~","~~"),"*","~*"),إعدادات_الأنواع!$A$4:$E$40,5,FALSE()),0)) -> 500 | N15: =IF(OR(K15="لم يدفع",K15="تأمين فقط",K15="اشتراك 300",B15=""),"",IFERROR(VLOOKUP(SUBSTITUTE(SUBSTITUTE(H15,"~","~~"),"*","~*"),إعدادات_الأنواع!$A$4:$F$40,6,FALSE()),0)) -> 1000 | O15: =IF(K15="لم يدفع","",IF(L15="","",IF(N15="",L15+M15,L15+M15))) -> 1800 | P15: =IF(B15="","",IF(K15="لم يدفع","🔒 مجمدة",IF(J15="","",IF(J15<TODAY(),"⛔ منتهي - يتطلب تجديد",IF(J15-5<=TODAY(),"⚠️ قريب الانتهاء","✅ ساري"))))) -> ✅ ساري | Q15: الأحد والأربعاء | R15: 9:00-10:00 | S15: =IF(B15="","",COUNTA(التجديد!E15:E15)) -> 0 | T15: =IF(B15="","",IFERROR(VLOOKUP(SUBSTITUTE(SUBSTITUTE(H15,"~","~~"),"*","~*"),إعدادات_الأنواع!$A$4:$B$40,2,FALSE()),"?")) -> RCS
A16: =IF(B16="","",IF(T16="?","⚠️ نوع غير معرف",T16&TEXT(COUNTIFS($T$3:T16,T16),"000"))) -> RCS014 | B16: قدو شريف | C16: صفاء سلسبيل | D16: 43285 | E16: أنثى | F16: =IF(D16="","",DATEDIF(D16,TODAY(),"Y")) -> 8 | H16: / | I16: 46194 | J16: =IF(I16="","",I16+30) -> 46224 | K16: مدفوع | L16: =IF(OR(K16="لم يدفع",B16=""),"",IF(K16="تأمين فقط",0,IF(K16="اشتراك 300",300,IF(F16<14,IFERROR(VLOOKUP(SUBSTITUTE(SUBSTITUTE(H16,"~","~~"),"*","~*"),إعدادات_الأنواع!$A$4:$D$40,3,FALSE()),0),IFERROR(VLOOKUP(SUBSTITUTE(SUBSTITUTE(H16,"~","~~"),"*","~*"),إعدادات_الأنواع!$A$4:$D$40,4,FALSE()),0))))) -> 1300 | M16: =IF(OR(K16="لم يدفع",B16=""),"",IFERROR(VLOOKUP(SUBSTITUTE(SUBSTITUTE(H16,"~","~~"),"*","~*"),إعدادات_الأنواع!$A$4:$E$40,5,FALSE()),0)) -> 500 | N16: =IF(OR(K16="لم يدفع",K16="تأمين فقط",K16="اشتراك 300",B16=""),"",IFERROR(VLOOKUP(SUBSTITUTE(SUBSTITUTE(H16,"~","~~"),"*","~*"),إعدادات_الأنواع!$A$4:$F$40,6,FALSE()),0)) -> 1000 | O16: =IF(K16="لم يدفع","",IF(L16="","",IF(N16="",L16+M16,L16+M16))) -> 1800 | P16: =IF(B16="","",IF(K16="لم يدفع","🔒 مجمدة",IF(J16="","",IF(J16<TODAY(),"⛔ منتهي - يتطلب تجديد",IF(J16-5<=TODAY(),"⚠️ قريب الانتهاء","✅ ساري"))))) -> ✅ ساري | Q16: الأحد والأربعاء | R16: 9:00-10:00 | S16: =IF(B16="","",COUNTA(التجديد!E16:E16)) -> 0 | T16: =IF(B16="","",IFERROR(VLOOKUP(SUBSTITUTE(SUBSTITUTE(H16,"~","~~"),"*","~*"),إعدادات_الأنواع!$A$4:$B$40,2,FALSE()),"?")) -> RCS
A17: =IF(B17="","",IF(T17="?","⚠️ نوع غير معرف",T17&TEXT(COUNTIFS($T$3:T17,T17),"000"))) -> RCS015 | B17: قدو شريف | C17: ثراء كوثر | D17: 42925 | E17: أنثى | F17: =IF(D17="","",DATEDIF(D17,TODAY(),"Y")) -> 9 | H17: / | I17: 46194 | J17: =IF(I17="","",I17+30) -> 46224 | K17: مدفوع | L17: =IF(OR(K17="لم يدفع",B17=""),"",IF(K17="تأمين فقط",0,IF(K17="اشتراك 300",300,IF(F17<14,IFERROR(VLOOKUP(SUBSTITUTE(SUBSTITUTE(H17,"~","~~"),"*","~*"),إعدادات_الأنواع!$A$4:$D$40,3,FALSE()),0),IFERROR(VLOOKUP(SUBSTITUTE(SUBSTITUTE(H17,"~","~~"),"*","~*"),إعدادات_الأنواع!$A$4:$D$40,4,FALSE()),0))))) -> 1300 | M17: =IF(OR(K17="لم يدفع",B17=""),"",IFERROR(VLOOKUP(SUBSTITUTE(SUBSTITUTE(H17,"~","~~"),"*","~*"),إعدادات_الأنواع!$A$4:$E$40,5,FALSE()),0)) -> 500 | N17: =IF(OR(K17="لم يدفع",K17="تأمين فقط",K17="اشتراك 300",B17=""),"",IFERROR(VLOOKUP(SUBSTITUTE(SUBSTITUTE(H17,"~","~~"),"*","~*"),إعدادات_الأنواع!$A$4:$F$40,6,FALSE()),0)) -> 1000 | O17: =IF(K17="لم يدفع","",IF(L17="","",IF(N17="",L17+M17,L17+M17))) -> 1800 | P17: =IF(B17="","",IF(K17="لم يدفع","🔒 مجمدة",IF(J17="","",IF(J17<TODAY(),"⛔ منتهي - يتطلب تجديد",IF(J17-5<=TODAY(),"⚠️ قريب الانتهاء","✅ ساري"))))) -> ✅ ساري | Q17: الأحد والأربعاء | R17: 9:00-10:00 | S17: =IF(B17="","",COUNTA(التجديد!E17:E17)) -> 0 | T17: =IF(B17="","",IFERROR(VLOOKUP(SUBSTITUTE(SUBSTITUTE(H17,"~","~~"),"*","~*"),إعدادات_الأنواع!$A$4:$B$40,2,FALSE()),"?")) -> RCS
A18: =IF(B18="","",IF(T18="?","⚠️ نوع غير معرف",T18&TEXT(COUNTIFS($T$3:T18,T18),"000"))) -> RCS016 | B18: يزيد | C18: هناء ياسمين | D18: 42770 | E18: أنثى | F18: =IF(D18="","",DATEDIF(D18,TODAY(),"Y")) -> 9 | H18: / | I18: 46197 | J18: =IF(I18="","",I18+30) -> 46227 | K18: مدفوع | L18: =IF(OR(K18="لم يدفع",B18=""),"",IF(K18="تأمين فقط",0,IF(K18="اشتراك 300",300,IF(F18<14,IFERROR(VLOOKUP(SUBSTITUTE(SUBSTITUTE(H18,"~","~~"),"*","~*"),إعدادات_الأنواع!$A$4:$D$40,3,FALSE()),0),IFERROR(VLOOKUP(SUBSTITUTE(SUBSTITUTE(H18,"~","~~"),"*","~*"),إعدادات_الأنواع!$A$4:$D$40,4,FALSE()),0))))) -> 1300 | M18: =IF(OR(K18="لم يدفع",B18=""),"",IFERROR(VLOOKUP(SUBSTITUTE(SUBSTITUTE(H18,"~","~~"),"*","~*"),إعدادات_الأنواع!$A$4:$E$40,5,FALSE()),0)) -> 500 | N18: =IF(OR(K18="لم يدفع",K18="تأمين فقط",K18="اشتراك 300",B18=""),"",IFERROR(VLOOKUP(SUBSTITUTE(SUBSTITUTE(H18,"~","~~"),"*","~*"),إعدادات_الأنواع!$A$4:$F$40,6,FALSE()),0)) -> 1000 | O18: =IF(K18="لم يدفع","",IF(L18="","",IF(N18="",L18+M18,L18+M18))) -> 1800 | P18: =IF(B18="","",IF(K18="لم يدفع","🔒 مجمدة",IF(J18="","",IF(J18<TODAY(),"⛔ منتهي - يتطلب تجديد",IF(J18-5<=TODAY(),"⚠️ قريب الانتهاء","✅ ساري"))))) -> ✅ ساري | Q18: الأحد والأربعاء | R18: 9:00-10:00 | S18: =IF(B18="","",COUNTA(التجديد!E18:E18)) -> 0 | T18: =IF(B18="","",IFERROR(VLOOKUP(SUBSTITUTE(SUBSTITUTE(H18,"~","~~"),"*","~*"),إعدادات_الأنواع!$A$4:$B$40,2,FALSE()),"?")) -> RCS
A19: =IF(B19="","",IF(T19="?","⚠️ نوع غير معرف",T19&TEXT(COUNTIFS($T$3:T19,T19),"000"))) -> RCS017 | B19: غوت | C19: محمد الامين | D19: 41969 | E19: ذكر | F19: =IF(D19="","",DATEDIF(D19,TODAY(),"Y")) -> 11 | G19: A+ | H19: / | I19: 46194 | J19: =IF(I19="","",I19+30) -> 46224 | K19: مدفوع | L19: =IF(OR(K19="لم يدفع",B19=""),"",IF(K19="تأمين فقط",0,IF(K19="اشتراك 300",300,IF(F19<14,IFERROR(VLOOKUP(SUBSTITUTE(SUBSTITUTE(H19,"~","~~"),"*","~*"),إعدادات_الأنواع!$A$4:$D$40,3,FALSE()),0),IFERROR(VLOOKUP(SUBSTITUTE(SUBSTITUTE(H19,"~","~~"),"*","~*"),إعدادات_الأنواع!$A$4:$D$40,4,FALSE()),0))))) -> 1300 | M19: =IF(OR(K19="لم يدفع",B19=""),"",IFERROR(VLOOKUP(SUBSTITUTE(SUBSTITUTE(H19,"~","~~"),"*","~*"),إعدادات_الأنواع!$A$4:$E$40,5,FALSE()),0)) -> 500 | N19: =IF(OR(K19="لم يدفع",K19="تأمين فقط",K19="اشتراك 300",B19=""),"",IFERROR(VLOOKUP(SUBSTITUTE(SUBSTITUTE(H19,"~","~~"),"*","~*"),إعدادات_الأنواع!$A$4:$F$40,6,FALSE()),0)) -> 1000 | O19: =IF(K19="لم يدفع","",IF(L19="","",IF(N19="",L19+M19,L19+M19))) -> 1800 | P19: =IF(B19="","",IF(K19="لم يدفع","🔒 مجمدة",IF(J19="","",IF(J19<TODAY(),"⛔ منتهي - يتطلب تجديد",IF(J19-5<=TODAY(),"⚠️ قريب الانتهاء","✅ ساري"))))) -> ✅ ساري | Q19: الأحد والأربعاء | R19: 10:00-11:00 | S19: =IF(B19="","",COUNTA(التجديد!E19:E19)) -> 0 | T19: =IF(B19="","",IFERROR(VLOOKUP(SUBSTITUTE(SUBSTITUTE(H19,"~","~~"),"*","~*"),إعدادات_الأنواع!$A$4:$B$40,2,FALSE()),"?")) -> RCS
A20: =IF(B20="","",IF(T20="?","⚠️ نوع غير معرف",T20&TEXT(COUNTIFS($T$3:T20,T20),"000"))) -> RCS018 | B20: بوعناني | C20: وصال أنفال | D20: 42235 | E20: أنثى | F20: =IF(D20="","",DATEDIF(D20,TODAY(),"Y")) -> 10 | H20: / | I20: 46197 | J20: =IF(I20="","",I20+30) -> 46227 | K20: مدفوع | L20: =IF(OR(K20="لم يدفع",B20=""),"",IF(K20="تأمين فقط",0,IF(K20="اشتراك 300",300,IF(F20<14,IFERROR(VLOOKUP(SUBSTITUTE(SUBSTITUTE(H20,"~","~~"),"*","~*"),إعدادات_الأنواع!$A$4:$D$40,3,FALSE()),0),IFERROR(VLOOKUP(SUBSTITUTE(SUBSTITUTE(H20,"~","~~"),"*","~*"),إعدادات_الأنواع!$A$4:$D$40,4,FALSE()),0))))) -> 1300 | M20: =IF(OR(K20="لم يدفع",B20=""),"",IFERROR(VLOOKUP(SUBSTITUTE(SUBSTITUTE(H20,"~","~~"),"*","~*"),إعدادات_الأنواع!$A$4:$E$40,5,FALSE()),0)) -> 500 | N20: =IF(OR(K20="لم يدفع",K20="تأمين فقط",K20="اشتراك 300",B20=""),"",IFERROR(VLOOKUP(SUBSTITUTE(SUBSTITUTE(H20,"~","~~"),"*","~*"),إعدادات_الأنواع!$A$4:$F$40,6,FALSE()),0)) -> 1000 | O20: =IF(K20="لم يدفع","",IF(L20="","",IF(N20="",L20+M20,L20+M20))) -> 1800 | P20: =IF(B20="","",IF(K20="لم يدفع","🔒 مجمدة",IF(J20="","",IF(J20<TODAY(),"⛔ منتهي - يتطلب تجديد",IF(J20-5<=TODAY(),"⚠️ قريب الانتهاء","✅ ساري"))))) -> ✅ ساري | Q20: الأحد والأربعاء | R20: 9:00-10:00 | S20: =IF(B20="","",COUNTA(التجديد!E20:E20)) -> 0 | T20: =IF(B20="","",IFERROR(VLOOKUP(SUBSTITUTE(SUBSTITUTE(H20,"~","~~"),"*","~*"),إعدادات_الأنواع!$A$4:$B$40,2,FALSE()),"?")) -> RCS
A21: =IF(B21="","",IF(T21="?","⚠️ نوع غير معرف",T21&TEXT(COUNTIFS($T$3:T21,T21),"000"))) -> RCS019 | B21: بن دامو | C21: حبيب الله | D21: 42071 | E21: ذكر | F21: =IF(D21="","",DATEDIF(D21,TODAY(),"Y")) -> 11 | H21: / | I21: 46194 | J21: =IF(I21="","",I21+30) -> 46224 | K21: مدفوع | L21: =IF(OR(K21="لم يدفع",B21=""),"",IF(K21="تأمين فقط",0,IF(K21="اشتراك 300",300,IF(F21<14,IFERROR(VLOOKUP(SUBSTITUTE(SUBSTITUTE(H21,"~","~~"),"*","~*"),إعدادات_الأنواع!$A$4:$D$40,3,FALSE()),0),IFERROR(VLOOKUP(SUBSTITUTE(SUBSTITUTE(H21,"~","~~"),"*","~*"),إعدادات_الأنواع!$A$4:$D$40,4,FALSE()),0))))) -> 1300 | M21: =IF(OR(K21="لم يدفع",B21=""),"",IFERROR(VLOOKUP(SUBSTITUTE(SUBSTITUTE(H21,"~","~~"),"*","~*"),إعدادات_الأنواع!$A$4:$E$40,5,FALSE()),0)) -> 500 | N21: =IF(OR(K21="لم يدفع",K21="تأمين فقط",K21="اشتراك 300",B21=""),"",IFERROR(VLOOKUP(SUBSTITUTE(SUBSTITUTE(H21,"~","~~"),"*","~*"),إعدادات_الأنواع!$A$4:$F$40,6,FALSE()),0)) -> 1000 | O21: =IF(K21="لم يدفع","",IF(L21="","",IF(N21="",L21+M21,L21+M21))) -> 1800 | P21: =IF(B21="","",IF(K21="لم يدفع","🔒 مجمدة",IF(J21="","",IF(J21<TODAY(),"⛔ منتهي - يتطلب تجديد",IF(J21-5<=TODAY(),"⚠️ قريب الانتهاء","✅ ساري"))))) -> ✅ ساري | Q21: الأحد والأربعاء | R21: 10:00-11:00 | S21: =IF(B21="","",COUNTA(التجديد!E21:E21)) -> 0 | T21: =IF(B21="","",IFERROR(VLOOKUP(SUBSTITUTE(SUBSTITUTE(H21,"~","~~"),"*","~*"),إعدادات_الأنواع!$A$4:$B$40,2,FALSE()),"?")) -> RCS
A22: =IF(B22="","",IF(T22="?","⚠️ نوع غير معرف",T22&TEXT(COUNTIFS($T$3:T22,T22),"000"))) -> RCS020 | B22: خايف | C22: أيمن | D22: 41636 | E22: ذكر | F22: =IF(D22="","",DATEDIF(D22,TODAY(),"Y")) -> 12 | H22: / | I22: 46194 | J22: =IF(I22="","",I22+30) -> 46224 | K22: مدفوع | L22: =IF(OR(K22="لم يدفع",B22=""),"",IF(K22="تأمين فقط",0,IF(K22="اشتراك 300",300,IF(F22<14,IFERROR(VLOOKUP(SUBSTITUTE(SUBSTITUTE(H22,"~","~~"),"*","~*"),إعدادات_الأنواع!$A$4:$D$40,3,FALSE()),0),IFERROR(VLOOKUP(SUBSTITUTE(SUBSTITUTE(H22,"~","~~"),"*","~*"),إعدادات_الأنواع!$A$4:$D$40,4,FALSE()),0))))) -> 1300 | M22: =IF(OR(K22="لم يدفع",B22=""),"",IFERROR(VLOOKUP(SUBSTITUTE(SUBSTITUTE(H22,"~","~~"),"*","~*"),إعدادات_الأنواع!$A$4:$E$40,5,FALSE()),0)) -> 500 | N22: =IF(OR(K22="لم يدفع",K22="تأمين فقط",K22="اشتراك 300",B22=""),"",IFERROR(VLOOKUP(SUBSTITUTE(SUBSTITUTE(H22,"~","~~"),"*","~*"),إعدادات_الأنواع!$A$4:$F$40,6,FALSE()),0)) -> 1000 | O22: =IF(K22="لم يدفع","",IF(L22="","",IF(N22="",L22+M22,L22+M22))) -> 1800 | P22: =IF(B22="","",IF(K22="لم يدفع","🔒 مجمدة",IF(J22="","",IF(J22<TODAY(),"⛔ منتهي - يتطلب تجديد",IF(J22-5<=TODAY(),"⚠️ قريب الانتهاء","✅ ساري"))))) -> ✅ ساري | Q22: الأحد والأربعاء | R22: 10:00-11:00 | S22: =IF(B22="","",COUNTA(التجديد!E22:E22)) -> 0 | T22: =IF(B22="","",IFERROR(VLOOKUP(SUBSTITUTE(SUBSTITUTE(H22,"~","~~"),"*","~*"),إعدادات_الأنواع!$A$4:$B$40,2,FALSE()),"?")) -> RCS
A23: =IF(B23="","",IF(T23="?","⚠️ نوع غير معرف",T23&TEXT(COUNTIFS($T$3:T23,T23),"000"))) -> RCS021 | B23: عقيدة | C23: يونس بهاء الدين | D23: 41922 | E23: ذكر | F23: =IF(D23="","",DATEDIF(D23,TODAY(),"Y")) -> 11 | H23: / | I23: 46194 | J23: =IF(I23="","",I23+30) -> 46224 | K23: مدفوع | L23: =IF(OR(K23="لم يدفع",B23=""),"",IF(K23="تأمين فقط",0,IF(K23="اشتراك 300",300,IF(F23<14,IFERROR(VLOOKUP(SUBSTITUTE(SUBSTITUTE(H23,"~","~~"),"*","~*"),إعدادات_الأنواع!$A$4:$D$40,3,FALSE()),0),IFERROR(VLOOKUP(SUBSTITUTE(SUBSTITUTE(H23,"~","~~"),"*","~*"),إعدادات_الأنواع!$A$4:$D$40,4,FALSE()),0))))) -> 1300 | M23: =IF(OR(K23="لم يدفع",B23=""),"",IFERROR(VLOOKUP(SUBSTITUTE(SUBSTITUTE(H23,"~","~~"),"*","~*"),إعدادات_الأنواع!$A$4:$E$40,5,FALSE()),0)) -> 500 | N23: =IF(OR(K23="لم يدفع",K23="تأمين فقط",K23="اشتراك 300",B23=""),"",IFERROR(VLOOKUP(SUBSTITUTE(SUBSTITUTE(H23,"~","~~"),"*","~*"),إعدادات_الأنواع!$A$4:$F$40,6,FALSE()),0)) -> 1000 | O23: =IF(K23="لم يدفع","",IF(L23="","",IF(N23="",L23+M23,L23+M23))) -> 1800 | P23: =IF(B23="","",IF(K23="لم يدفع","🔒 مجمدة",IF(J23="","",IF(J23<TODAY(),"⛔ منتهي - يتطلب تجديد",IF(J23-5<=TODAY(),"⚠️ قريب الانتهاء","✅ ساري"))))) -> ✅ ساري | Q23: الأحد والأربعاء | R23: 10:00-11:00 | S23: =IF(B23="","",COUNTA(التجديد!E23:E23)) -> 0 | T23: =IF(B23="","",IFERROR(VLOOKUP(SUBSTITUTE(SUBSTITUTE(H23,"~","~~"),"*","~*"),إعدادات_الأنواع!$A$4:$B$40,2,FALSE()),"?")) -> RCS
A24: =IF(B24="","",IF(T24="?","⚠️ نوع غير معرف",T24&TEXT(COUNTIFS($T$3:T24,T24),"000"))) -> RCS022 | B24: عقيدة | C24: أيوب عبد الاله | D24: 43772 | E24: ذكر | F24: =IF(D24="","",DATEDIF(D24,TODAY(),"Y")) -> 6 | H24: / | I24: 46194 | J24: =IF(I24="","",I24+30) -> 46224 | K24: مدفوع | L24: =IF(OR(K24="لم يدفع",B24=""),"",IF(K24="تأمين فقط",0,IF(K24="اشتراك 300",300,IF(F24<14,IFERROR(VLOOKUP(SUBSTITUTE(SUBSTITUTE(H24,"~","~~"),"*","~*"),إعدادات_الأنواع!$A$4:$D$40,3,FALSE()),0),IFERROR(VLOOKUP(SUBSTITUTE(SUBSTITUTE(H24,"~","~~"),"*","~*"),إعدادات_الأنواع!$A$4:$D$40,4,FALSE()),0))))) -> 1300 | M24: =IF(OR(K24="لم يدفع",B24=""),"",IFERROR(VLOOKUP(SUBSTITUTE(SUBSTITUTE(H24,"~","~~"),"*","~*"),إعدادات_الأنواع!$A$4:$E$40,5,FALSE()),0)) -> 500 | N24: =IF(OR(K24="لم يدفع",K24="تأمين فقط",K24="اشتراك 300",B24=""),"",IFERROR(VLOOKUP(SUBSTITUTE(SUBSTITUTE(H24,"~","~~"),"*","~*"),إعدادات_الأنواع!$A$4:$F$40,6,FALSE()),0)) -> 1000 | O24: =IF(K24="لم يدفع","",IF(L24="","",IF(N24="",L24+M24,L24+M24))) -> 1800 | P24: =IF(B24="","",IF(K24="لم يدفع","🔒 مجمدة",IF(J24="","",IF(J24<TODAY(),"⛔ منتهي - يتطلب تجديد",IF(J24-5<=TODAY(),"⚠️ قريب الانتهاء","✅ ساري"))))) -> ✅ ساري | Q24: الأحد والأربعاء | R24: 10:00-11:00 | S24: =IF(B24="","",COUNTA(التجديد!E24:E24)) -> 0 | T24: =IF(B24="","",IFERROR(VLOOKUP(SUBSTITUTE(SUBSTITUTE(H24,"~","~~"),"*","~*"),إعدادات_الأنواع!$A$4:$B$40,2,FALSE()),"?")) -> RCS
A25: =IF(B25="","",IF(T25="?","⚠️ نوع غير معرف",T25&TEXT(COUNTIFS($T$3:T25,T25),"000"))) -> RCS023 | B25: بوعناني | C25: فؤاد | D25: 39118 | E25: ذكر | F25: =IF(D25="","",DATEDIF(D25,TODAY(),"Y")) -> 19 | G25: A+ | H25: DJS | I25: 46194 | J25: =IF(I25="","",I25+30) -> 46224 | K25: مدفوع | L25: =IF(OR(K25="لم يدفع",B25=""),"",IF(K25="تأمين فقط",0,IF(K25="اشتراك 300",300,IF(F25<14,IFERROR(VLOOKUP(SUBSTITUTE(SUBSTITUTE(H25,"~","~~"),"*","~*"),إعدادات_الأنواع!$A$4:$D$40,3,FALSE()),0),IFERROR(VLOOKUP(SUBSTITUTE(SUBSTITUTE(H25,"~","~~"),"*","~*"),إعدادات_الأنواع!$A$4:$D$40,4,FALSE()),0))))) -> 500 | M25: =IF(OR(K25="لم يدفع",B25=""),"",IFERROR(VLOOKUP(SUBSTITUTE(SUBSTITUTE(H25,"~","~~"),"*","~*"),إعدادات_الأنواع!$A$4:$E$40,5,FALSE()),0)) -> 500 | N25: =IF(OR(K25="لم يدفع",K25="تأمين فقط",K25="اشتراك 300",B25=""),"",IFERROR(VLOOKUP(SUBSTITUTE(SUBSTITUTE(H25,"~","~~"),"*","~*"),إعدادات_الأنواع!$A$4:$F$40,6,FALSE()),0)) -> 0 | O25: =IF(K25="لم يدفع","",IF(L25="","",IF(N25="",L25+M25,L25+M25))) -> 1000 | P25: =IF(B25="","",IF(K25="لم يدفع","🔒 مجمدة",IF(J25="","",IF(J25<TODAY(),"⛔ منتهي - يتطلب تجديد",IF(J25-5<=TODAY(),"⚠️ قريب الانتهاء","✅ ساري"))))) -> ✅ ساري | Q25: الأحد والأربعاء | R25: 20:00-21:00 | S25: =IF(B25="","",COUNTA(التجديد!E25:E25)) -> 0 | T25: =IF(B25="","",IFERROR(VLOOKUP(SUBSTITUTE(SUBSTITUTE(H25,"~","~~"),"*","~*"),إعدادات_الأنواع!$A$4:$B$40,2,FALSE()),"?")) -> RCS
A26: =IF(B26="","",IF(T26="?","⚠️ نوع غير معرف",T26&TEXT(COUNTIFS($T$3:T26,T26),"000"))) -> RCS024 | B26: عليلي | C26: محسن عبد الإله | D26: 39422 | E26: ذكر | F26: =IF(D26="","",DATEDIF(D26,TODAY(),"Y")) -> 18 | G26: O+ | H26: / | I26: 46194 | J26: =IF(I26="","",I26+30) -> 46224 | K26: مدفوع | L26: =IF(OR(K26="لم يدفع",B26=""),"",IF(K26="تأمين فقط",0,IF(K26="اشتراك 300",300,IF(F26<14,IFERROR(VLOOKUP(SUBSTITUTE(SUBSTITUTE(H26,"~","~~"),"*","~*"),إعدادات_الأنواع!$A$4:$D$40,3,FALSE()),0),IFERROR(VLOOKUP(SUBSTITUTE(SUBSTITUTE(H26,"~","~~"),"*","~*"),إعدادات_الأنواع!$A$4:$D$40,4,FALSE()),0))))) -> 1500 | M26: =IF(OR(K26="لم يدفع",B26=""),"",IFERROR(VLOOKUP(SUBSTITUTE(SUBSTITUTE(H26,"~","~~"),"*","~*"),إعدادات_الأنواع!$A$4:$E$40,5,FALSE()),0)) -> 500 | N26: =IF(OR(K26="لم يدفع",K26="تأمين فقط",K26="اشتراك 300",B26=""),"",IFERROR(VLOOKUP(SUBSTITUTE(SUBSTITUTE(H26,"~","~~"),"*","~*"),إعدادات_الأنواع!$A$4:$F$40,6,FALSE()),0)) -> 1000 | O26: =IF(K26="لم يدفع","",IF(L26="","",IF(N26="",L26+M26,L26+M26))) -> 2000 | P26: =IF(B26="","",IF(K26="لم يدفع","🔒 مجمدة",IF(J26="","",IF(J26<TODAY(),"⛔ منتهي - يتطلب تجديد",IF(J26-5<=TODAY(),"⚠️ قريب الانتهاء","✅ ساري"))))) -> ✅ ساري | Q26: الأحد والأربعاء | R26: 19:00-20:00 | S26: =IF(B26="","",COUNTA(التجديد!E26:E26)) -> 0 | T26: =IF(B26="","",IFERROR(VLOOKUP(SUBSTITUTE(SUBSTITUTE(H26,"~","~~"),"*","~*"),إعدادات_الأنواع!$A$4:$B$40,2,FALSE()),"?")) -> RCS
A27: =IF(B27="","",IF(T27="?","⚠️ نوع غير معرف",T27&TEXT(COUNTIFS($T$3:T27,T27),"000"))) -> RCS025 | B27: صايم | C27: علي | D27: 39652 | E27: ذكر | F27: =IF(D27="","",DATEDIF(D27,TODAY(),"Y")) -> 17 | G27: A+ | H27: / | I27: 46194 | J27: =IF(I27="","",I27+30) -> 46224 | K27: مدفوع | L27: =IF(OR(K27="لم يدفع",B27=""),"",IF(K27="تأمين فقط",0,IF(K27="اشتراك 300",300,IF(F27<14,IFERROR(VLOOKUP(SUBSTITUTE(SUBSTITUTE(H27,"~","~~"),"*","~*"),إعدادات_الأنواع!$A$4:$D$40,3,FALSE()),0),IFERROR(VLOOKUP(SUBSTITUTE(SUBSTITUTE(H27,"~","~~"),"*","~*"),إعدادات_الأنواع!$A$4:$D$40,4,FALSE()),0))))) -> 1500 | M27: =IF(OR(K27="لم يدفع",B27=""),"",IFERROR(VLOOKUP(SUBSTITUTE(SUBSTITUTE(H27,"~","~~"),"*","~*"),إعدادات_الأنواع!$A$4:$E$40,5,FALSE()),0)) -> 500 | N27: =IF(OR(K27="لم يدفع",K27="تأمين فقط",K27="اشتراك 300",B27=""),"",IFERROR(VLOOKUP(SUBSTITUTE(SUBSTITUTE(H27,"~","~~"),"*","~*"),إعدادات_الأنواع!$A$4:$F$40,6,FALSE()),0)) -> 1000 | O27: =IF(K27="لم يدفع","",IF(L27="","",IF(N27="",L27+M27,L27+M27))) -> 2000 | P27: =IF(B27="","",IF(K27="لم يدفع","🔒 مجمدة",IF(J27="","",IF(J27<TODAY(),"⛔ منتهي - يتطلب تجديد",IF(J27-5<=TODAY(),"⚠️ قريب الانتهاء","✅ ساري"))))) -> ✅ ساري | Q27: الأحد والأربعاء | R27: 19:00-20:00 | S27: =IF(B27="","",COUNTA(التجديد!E27:E27)) -> 0 | T27: =IF(B27="","",IFERROR(VLOOKUP(SUBSTITUTE(SUBSTITUTE(H27,"~","~~"),"*","~*"),إعدادات_الأنواع!$A$4:$B$40,2,FALSE()),"?")) -> RCS
A28: =IF(B28="","",IF(T28="?","⚠️ نوع غير معرف",T28&TEXT(COUNTIFS($T$3:T28,T28),"000"))) -> RCS026 | B28: برياح | C28: ادم | D28: 41796 | E28: ذكر | F28: =IF(D28="","",DATEDIF(D28,TODAY(),"Y")) -> 12 | H28: / | I28: 46194 | J28: =IF(I28="","",I28+30) -> 46224 | K28: مدفوع | L28: =IF(OR(K28="لم يدفع",B28=""),"",IF(K28="تأمين فقط",0,IF(K28="اشتراك 300",300,IF(F28<14,IFERROR(VLOOKUP(SUBSTITUTE(SUBSTITUTE(H28,"~","~~"),"*","~*"),إعدادات_الأنواع!$A$4:$D$40,3,FALSE()),0),IFERROR(VLOOKUP(SUBSTITUTE(SUBSTITUTE(H28,"~","~~"),"*","~*"),إعدادات_الأنواع!$A$4:$D$40,4,FALSE()),0))))) -> 1300 | M28: =IF(OR(K28="لم يدفع",B28=""),"",IFERROR(VLOOKUP(SUBSTITUTE(SUBSTITUTE(H28,"~","~~"),"*","~*"),إعدادات_الأنواع!$A$4:$E$40,5,FALSE()),0)) -> 500 | N28: =IF(OR(K28="لم يدفع",K28="تأمين فقط",K28="اشتراك 300",B28=""),"",IFERROR(VLOOKUP(SUBSTITUTE(SUBSTITUTE(H28,"~","~~"),"*","~*"),إعدادات_الأنواع!$A$4:$F$40,6,FALSE()),0)) -> 1000 | O28: =IF(K28="لم يدفع","",IF(L28="","",IF(N28="",L28+M28,L28+M28))) -> 1800 | P28: =IF(B28="","",IF(K28="لم يدفع","🔒 مجمدة",IF(J28="","",IF(J28<TODAY(),"⛔ منتهي - يتطلب تجديد",IF(J28-5<=TODAY(),"⚠️ قريب الانتهاء","✅ ساري"))))) -> ✅ ساري | Q28: الأحد والأربعاء | R28: 19:00-20:00 | S28: =IF(B28="","",COUNTA(التجديد!E28:E28)) -> 0 | T28: =IF(B28="","",IFERROR(VLOOKUP(SUBSTITUTE(SUBSTITUTE(H28,"~","~~"),"*","~*"),إعدادات_الأنواع!$A$4:$B$40,2,FALSE()),"?")) -> RCS
A29: =IF(B29="","",IF(T29="?","⚠️ نوع غير معرف",T29&TEXT(COUNTIFS($T$3:T29,T29),"000"))) -> RCS027 | B29: برياح | C29: يونس مصعب | D29: 40434 | E29: ذكر | F29: =IF(D29="","",DATEDIF(D29,TODAY(),"Y")) -> 15 | H29: / | I29: 46194 | J29: =IF(I29="","",I29+30) -> 46224 | K29: مدفوع | L29: =IF(OR(K29="لم يدفع",B29=""),"",IF(K29="تأمين فقط",0,IF(K29="اشتراك 300",300,IF(F29<14,IFERROR(VLOOKUP(SUBSTITUTE(SUBSTITUTE(H29,"~","~~"),"*","~*"),إعدادات_الأنواع!$A$4:$D$40,3,FALSE()),0),IFERROR(VLOOKUP(SUBSTITUTE(SUBSTITUTE(H29,"~","~~"),"*","~*"),إعدادات_الأنواع!$A$4:$D$40,4,FALSE()),0))))) -> 1500 | M29: =IF(OR(K29="لم يدفع",B29=""),"",IFERROR(VLOOKUP(SUBSTITUTE(SUBSTITUTE(H29,"~","~~"),"*","~*"),إعدادات_الأنواع!$A$4:$E$40,5,FALSE()),0)) -> 500 | N29: =IF(OR(K29="لم يدفع",K29="تأمين فقط",K29="اشتراك 300",B29=""),"",IFERROR(VLOOKUP(SUBSTITUTE(SUBSTITUTE(H29,"~","~~"),"*","~*"),إعدادات_الأنواع!$A$4:$F$40,6,FALSE()),0)) -> 1000 | O29: =IF(K29="لم يدفع","",IF(L29="","",IF(N29="",L29+M29,L29+M29))) -> 2000 | P29: =IF(B29="","",IF(K29="لم يدفع","🔒 مجمدة",IF(J29="","",IF(J29<TODAY(),"⛔ منتهي - يتطلب تجديد",IF(J29-5<=TODAY(),"⚠️ قريب الانتهاء","✅ ساري"))))) -> ✅ ساري | Q29: الأحد والأربعاء | R29: 19:00-20:00 | S29: =IF(B29="","",COUNTA(التجديد!E29:E29)) -> 0 | T29: =IF(B29="","",IFERROR(VLOOKUP(SUBSTITUTE(SUBSTITUTE(H29,"~","~~"),"*","~*"),إعدادات_الأنواع!$A$4:$B$40,2,FALSE()),"?")) -> RCS
A30: =IF(B30="","",IF(T30="?","⚠️ نوع غير معرف",T30&TEXT(COUNTIFS($T$3:T30,T30),"000"))) -> RCS028 | B30: دادي | C30: مروان رشيد | D30: 40949 | E30: ذكر | F30: =IF(D30="","",DATEDIF(D30,TODAY(),"Y")) -> 14 | G30: O+ | H30: / | I30: 46194 | J30: =IF(I30="","",I30+30) -> 46224 | K30: مدفوع | L30: =IF(OR(K30="لم يدفع",B30=""),"",IF(K30="تأمين فقط",0,IF(K30="اشتراك 300",300,IF(F30<14,IFERROR(VLOOKUP(SUBSTITUTE(SUBSTITUTE(H30,"~","~~"),"*","~*"),إعدادات_الأنواع!$A$4:$D$40,3,FALSE()),0),IFERROR(VLOOKUP(SUBSTITUTE(SUBSTITUTE(H30,"~","~~"),"*","~*"),إعدادات_الأنواع!$A$4:$D$40,4,FALSE()),0))))) -> 1500 | M30: =IF(OR(K30="لم يدفع",B30=""),"",IFERROR(VLOOKUP(SUBSTITUTE(SUBSTITUTE(H30,"~","~~"),"*","~*"),إعدادات_الأنواع!$A$4:$E$40,5,FALSE()),0)) -> 500 | N30: =IF(OR(K30="لم يدفع",K30="تأمين فقط",K30="اشتراك 300",B30=""),"",IFERROR(VLOOKUP(SUBSTITUTE(SUBSTITUTE(H30,"~","~~"),"*","~*"),إعدادات_الأنواع!$A$4:$F$40,6,FALSE()),0)) -> 1000 | O30: =IF(K30="لم يدفع","",IF(L30="","",IF(N30="",L30+M30,L30+M30))) -> 2000 | P30: =IF(B30="","",IF(K30="لم يدفع","🔒 مجمدة",IF(J30="","",IF(J30<TODAY(),"⛔ منتهي - يتطلب تجديد",IF(J30-5<=TODAY(),"⚠️ قريب الانتهاء","✅ ساري"))))) -> ✅ ساري | Q30: الأحد والأربعاء | R30: 19:00-20:00 | S30: =IF(B30="","",COUNTA(التجديد!E30:E30)) -> 0 | T30: =IF(B30="","",IFERROR(VLOOKUP(SUBSTITUTE(SUBSTITUTE(H30,"~","~~"),"*","~*"),إعدادات_الأنواع!$A$4:$B$40,2,FALSE()),"?")) -> RCS
A31: =IF(B31="","",IF(T31="?","⚠️ نوع غير معرف",T31&TEXT(COUNTIFS($T$3:T31,T31),"000"))) -> RCS029 | B31: قوراري | C31: محمد السعيد | D31: 40103 | E31: ذكر | F31: =IF(D31="","",DATEDIF(D31,TODAY(),"Y")) -> 16 | G31: A+ | H31: / | I31: 46194 | J31: =IF(I31="","",I31+30) -> 46224 | K31: مدفوع | L31: =IF(OR(K31="لم يدفع",B31=""),"",IF(K31="تأمين فقط",0,IF(K31="اشتراك 300",300,IF(F31<14,IFERROR(VLOOKUP(SUBSTITUTE(SUBSTITUTE(H31,"~","~~"),"*","~*"),إعدادات_الأنواع!$A$4:$D$40,3,FALSE()),0),IFERROR(VLOOKUP(SUBSTITUTE(SUBSTITUTE(H31,"~","~~"),"*","~*"),إعدادات_الأنواع!$A$4:$D$40,4,FALSE()),0))))) -> 1500 | M31: =IF(OR(K31="لم يدفع",B31=""),"",IFERROR(VLOOKUP(SUBSTITUTE(SUBSTITUTE(H31,"~","~~"),"*","~*"),إعدادات_الأنواع!$A$4:$E$40,5,FALSE()),0)) -> 500 | N31: =IF(OR(K31="لم يدفع",K31="تأمين فقط",K31="اشتراك 300",B31=""),"",IFERROR(VLOOKUP(SUBSTITUTE(SUBSTITUTE(H31,"~","~~"),"*","~*"),إعدادات_الأنواع!$A$4:$F$40,6,FALSE()),0)) -> 1000 | O31: =IF(K31="لم يدفع","",IF(L31="","",IF(N31="",L31+M31,L31+M31))) -> 2000 | P31: =IF(B31="","",IF(K31="لم يدفع","🔒 مجمدة",IF(J31="","",IF(J31<TODAY(),"⛔ منتهي - يتطلب تجديد",IF(J31-5<=TODAY(),"⚠️ قريب الانتهاء","✅ ساري"))))) -> ✅ ساري | Q31: الأحد والأربعاء | R31: 19:00-20:00 | S31: =IF(B31="","",COUNTA(التجديد!E31:E31)) -> 0 | T31: =IF(B31="","",IFERROR(VLOOKUP(SUBSTITUTE(SUBSTITUTE(H31,"~","~~"),"*","~*"),إعدادات_الأنواع!$A$4:$B$40,2,FALSE()),"?")) -> RCS
A32: =IF(B32="","",IF(T32="?","⚠️ نوع غير معرف",T32&TEXT(COUNTIFS($T$3:T32,T32),"000"))) -> RCS030 | B32: حمامي | C32: عبد الكريم | D32: 40834 | E32: ذكر | F32: =IF(D32="","",DATEDIF(D32,TODAY(),"Y")) -> 14 | G32: O+ | H32: / | I32: 46194 | J32: =IF(I32="","",I32+30) -> 46224 | K32: مدفوع | L32: =IF(OR(K32="لم يدفع",B32=""),"",IF(K32="تأمين فقط",0,IF(K32="اشتراك 300",300,IF(F32<14,IFERROR(VLOOKUP(SUBSTITUTE(SUBSTITUTE(H32,"~","~~"),"*","~*"),إعدادات_الأنواع!$A$4:$D$40,3,FALSE()),0),IFERROR(VLOOKUP(SUBSTITUTE(SUBSTITUTE(H32,"~","~~"),"*","~*"),إعدادات_الأنواع!$A$4:$D$40,4,FALSE()),0))))) -> 1500 | M32: =IF(OR(K32="لم يدفع",B32=""),"",IFERROR(VLOOKUP(SUBSTITUTE(SUBSTITUTE(H32,"~","~~"),"*","~*"),إعدادات_الأنواع!$A$4:$E$40,5,FALSE()),0)) -> 500 | N32: =IF(OR(K32="لم يدفع",K32="تأمين فقط",K32="اشتراك 300",B32=""),"",IFERROR(VLOOKUP(SUBSTITUTE(SUBSTITUTE(H32,"~","~~"),"*","~*"),إعدادات_الأنواع!$A$4:$F$40,6,FALSE()),0)) -> 1000 | O32: =IF(K32="لم يدفع","",IF(L32="","",IF(N32="",L32+M32,L32+M32))) -> 2000 | P32: =IF(B32="","",IF(K32="لم يدفع","🔒 مجمدة",IF(J32="","",IF(J32<TODAY(),"⛔ منتهي - يتطلب تجديد",IF(J32-5<=TODAY(),"⚠️ قريب الانتهاء","✅ ساري"))))) -> ✅ ساري | Q32: الأحد والأربعاء | R32: 19:00-20:00 | S32: =IF(B32="","",COUNTA(التجديد!E32:E32)) -> 0 | T32: =IF(B32="","",IFERROR(VLOOKUP(SUBSTITUTE(SUBSTITUTE(H32,"~","~~"),"*","~*"),إعدادات_الأنواع!$A$4:$B$40,2,FALSE()),"?")) -> RCS
A33: =IF(B33="","",IF(T33="?","⚠️ نوع غير معرف",T33&TEXT(COUNTIFS($T$3:T33,T33),"000"))) -> RCS031 | B33: مرتضى | C33: عبد الرزاق شيخ | D33: 39937 | E33: ذكر | F33: =IF(D33="","",DATEDIF(D33,TODAY(),"Y")) -> 17 | H33: / | I33: 46194 | J33: =IF(I33="","",I33+30) -> 46224 | K33: مدفوع | L33: =IF(OR(K33="لم يدفع",B33=""),"",IF(K33="تأمين فقط",0,IF(K33="اشتراك 300",300,IF(F33<14,IFERROR(VLOOKUP(SUBSTITUTE(SUBSTITUTE(H33,"~","~~"),"*","~*"),إعدادات_الأنواع!$A$4:$D$40,3,FALSE()),0),IFERROR(VLOOKUP(SUBSTITUTE(SUBSTITUTE(H33,"~","~~"),"*","~*"),إعدادات_الأنواع!$A$4:$D$40,4,FALSE()),0))))) -> 1500 | M33: =IF(OR(K33="لم يدفع",B33=""),"",IFERROR(VLOOKUP(SUBSTITUTE(SUBSTITUTE(H33,"~","~~"),"*","~*"),إعدادات_الأنواع!$A$4:$E$40,5,FALSE()),0)) -> 500 | N33: =IF(OR(K33="لم يدفع",K33="تأمين فقط",K33="اشتراك 300",B33=""),"",IFERROR(VLOOKUP(SUBSTITUTE(SUBSTITUTE(H33,"~","~~"),"*","~*"),إعدادات_الأنواع!$A$4:$F$40,6,FALSE()),0)) -> 1000 | O33: =IF(K33="لم يدفع","",IF(L33="","",IF(N33="",L33+M33,L33+M33))) -> 2000 | P33: =IF(B33="","",IF(K33="لم يدفع","🔒 مجمدة",IF(J33="","",IF(J33<TODAY(),"⛔ منتهي - يتطلب تجديد",IF(J33-5<=TODAY(),"⚠️ قريب الانتهاء","✅ ساري"))))) -> ✅ ساري | Q33: الأحد والأربعاء | R33: 19:00-20:00 | S33: =IF(B33="","",COUNTA(التجديد!E33:E33)) -> 0 | T33: =IF(B33="","",IFERROR(VLOOKUP(SUBSTITUTE(SUBSTITUTE(H33,"~","~~"),"*","~*"),إعدادات_الأنواع!$A$4:$B$40,2,FALSE()),"?")) -> RCS
A34: =IF(B34="","",IF(T34="?","⚠️ نوع غير معرف",T34&TEXT(COUNTIFS($T$3:T34,T34),"000"))) -> RCS032 | B34: بوكراع | C34: يوسف الصديق | D34: 41356 | E34: ذكر | F34: =IF(D34="","",DATEDIF(D34,TODAY(),"Y")) -> 13 | H34: / | I34: 46194 | J34: =IF(I34="","",I34+30) -> 46224 | K34: مدفوع | L34: =IF(OR(K34="لم يدفع",B34=""),"",IF(K34="تأمين فقط",0,IF(K34="اشتراك 300",300,IF(F34<14,IFERROR(VLOOKUP(SUBSTITUTE(SUBSTITUTE(H34,"~","~~"),"*","~*"),إعدادات_الأنواع!$A$4:$D$40,3,FALSE()),0),IFERROR(VLOOKUP(SUBSTITUTE(SUBSTITUTE(H34,"~","~~"),"*","~*"),إعدادات_الأنواع!$A$4:$D$40,4,FALSE()),0))))) -> 1300 | M34: =IF(OR(K34="لم يدفع",B34=""),"",IFERROR(VLOOKUP(SUBSTITUTE(SUBSTITUTE(H34,"~","~~"),"*","~*"),إعدادات_الأنواع!$A$4:$E$40,5,FALSE()),0)) -> 500 | N34: =IF(OR(K34="لم يدفع",K34="تأمين فقط",K34="اشتراك 300",B34=""),"",IFERROR(VLOOKUP(SUBSTITUTE(SUBSTITUTE(H34,"~","~~"),"*","~*"),إعدادات_الأنواع!$A$4:$F$40,6,FALSE()),0)) -> 1000 | O34: =IF(K34="لم يدفع","",IF(L34="","",IF(N34="",L34+M34,L34+M34))) -> 1800 | P34: =IF(B34="","",IF(K34="لم يدفع","🔒 مجمدة",IF(J34="","",IF(J34<TODAY(),"⛔ منتهي - يتطلب تجديد",IF(J34-5<=TODAY(),"⚠️ قريب الانتهاء","✅ ساري"))))) -> ✅ ساري | Q34: الأحد والأربعاء | R34: 19:00-20:00 | S34: =IF(B34="","",COUNTA(التجديد!E34:E34)) -> 0 | T34: =IF(B34="","",IFERROR(VLOOKUP(SUBSTITUTE(SUBSTITUTE(H34,"~","~~"),"*","~*"),إعدادات_الأنواع!$A$4:$B$40,2,FALSE()),"?")) -> RCS
A35: =IF(B35="","",IF(T35="?","⚠️ نوع غير معرف",T35&TEXT(COUNTIFS($T$3:T35,T35),"000"))) -> RCS033 | B35: لبوخ | C35: نصر الدين | D35: 40580 | E35: ذكر | F35: =IF(D35="","",DATEDIF(D35,TODAY(),"Y")) -> 15 | H35: / | I35: 46194 | J35: =IF(I35="","",I35+30) -> 46224 | K35: مدفوع | L35: =IF(OR(K35="لم يدفع",B35=""),"",IF(K35="تأمين فقط",0,IF(K35="اشتراك 300",300,IF(F35<14,IFERROR(VLOOKUP(SUBSTITUTE(SUBSTITUTE(H35,"~","~~"),"*","~*"),إعدادات_الأنواع!$A$4:$D$40,3,FALSE()),0),IFERROR(VLOOKUP(SUBSTITUTE(SUBSTITUTE(H35,"~","~~"),"*","~*"),إعدادات_الأنواع!$A$4:$D$40,4,FALSE()),0))))) -> 1500 | M35: =IF(OR(K35="لم يدفع",B35=""),"",IFERROR(VLOOKUP(SUBSTITUTE(SUBSTITUTE(H35,"~","~~"),"*","~*"),إعدادات_الأنواع!$A$4:$E$40,5,FALSE()),0)) -> 500 | N35: =IF(OR(K35="لم يدفع",K35="تأمين فقط",K35="اشتراك 300",B35=""),"",IFERROR(VLOOKUP(SUBSTITUTE(SUBSTITUTE(H35,"~","~~"),"*","~*"),إعدادات_الأنواع!$A$4:$F$40,6,FALSE()),0)) -> 1000 | O35: =IF(K35="لم يدفع","",IF(L35="","",IF(N35="",L35+M35,L35+M35))) -> 2000 | P35: =IF(B35="","",IF(K35="لم يدفع","🔒 مجمدة",IF(J35="","",IF(J35<TODAY(),"⛔ منتهي - يتطلب تجديد",IF(J35-5<=TODAY(),"⚠️ قريب الانتهاء","✅ ساري"))))) -> ✅ ساري | Q35: الأحد والأربعاء | R35: 19:00-20:00 | S35: =IF(B35="","",COUNTA(التجديد!E35:E35)) -> 0 | T35: =IF(B35="","",IFERROR(VLOOKUP(SUBSTITUTE(SUBSTITUTE(H35,"~","~~"),"*","~*"),إعدادات_الأنواع!$A$4:$B$40,2,FALSE()),"?")) -> RCS
A36: =IF(B36="","",IF(T36="?","⚠️ نوع غير معرف",T36&TEXT(COUNTIFS($T$3:T36,T36),"000"))) -> RCS034 | B36: جرفي | C36: حسين | D36: 38830 | E36: ذكر | F36: =IF(D36="","",DATEDIF(D36,TODAY(),"Y")) -> 20 | H36: / | I36: 46194 | J36: =IF(I36="","",I36+30) -> 46224 | K36: مدفوع | L36: =IF(OR(K36="لم يدفع",B36=""),"",IF(K36="تأمين فقط",0,IF(K36="اشتراك 300",300,IF(F36<14,IFERROR(VLOOKUP(SUBSTITUTE(SUBSTITUTE(H36,"~","~~"),"*","~*"),إعدادات_الأنواع!$A$4:$D$40,3,FALSE()),0),IFERROR(VLOOKUP(SUBSTITUTE(SUBSTITUTE(H36,"~","~~"),"*","~*"),إعدادات_الأنواع!$A$4:$D$40,4,FALSE()),0))))) -> 1500 | M36: =IF(OR(K36="لم يدفع",B36=""),"",IFERROR(VLOOKUP(SUBSTITUTE(SUBSTITUTE(H36,"~","~~"),"*","~*"),إعدادات_الأنواع!$A$4:$E$40,5,FALSE()),0)) -> 500 | N36: =IF(OR(K36="لم يدفع",K36="تأمين فقط",K36="اشتراك 300",B36=""),"",IFERROR(VLOOKUP(SUBSTITUTE(SUBSTITUTE(H36,"~","~~"),"*","~*"),إعدادات_الأنواع!$A$4:$F$40,6,FALSE()),0)) -> 1000 | O36: =IF(K36="لم يدفع","",IF(L36="","",IF(N36="",L36+M36,L36+M36))) -> 2000 | P36: =IF(B36="","",IF(K36="لم يدفع","🔒 مجمدة",IF(J36="","",IF(J36<TODAY(),"⛔ منتهي - يتطلب تجديد",IF(J36-5<=TODAY(),"⚠️ قريب الانتهاء","✅ ساري"))))) -> ✅ ساري | Q36: الأحد والأربعاء | R36: 19:00-20:00 | S36: =IF(B36="","",COUNTA(التجديد!E36:E36)) -> 0 | T36: =IF(B36="","",IFERROR(VLOOKUP(SUBSTITUTE(SUBSTITUTE(H36,"~","~~"),"*","~*"),إعدادات_الأنواع!$A$4:$B$40,2,FALSE()),"?")) -> RCS
A37: =IF(B37="","",IF(T37="?","⚠️ نوع غير معرف",T37&TEXT(COUNTIFS($T$3:T37,T37),"000"))) -> RCS035 | B37: راي | C37: أحمد الجيلالي | D37: 33975 | E37: ذكر | F37: =IF(D37="","",DATEDIF(D37,TODAY(),"Y")) -> 33 | H37: / | I37: 46194 | J37: =IF(I37="","",I37+30) -> 46224 | K37: مدفوع | L37: =IF(OR(K37="لم يدفع",B37=""),"",IF(K37="تأمين فقط",0,IF(K37="اشتراك 300",300,IF(F37<14,IFERROR(VLOOKUP(SUBSTITUTE(SUBSTITUTE(H37,"~","~~"),"*","~*"),إعدادات_الأنواع!$A$4:$D$40,3,FALSE()),0),IFERROR(VLOOKUP(SUBSTITUTE(SUBSTITUTE(H37,"~","~~"),"*","~*"),إعدادات_الأنواع!$A$4:$D$40,4,FALSE()),0))))) -> 1500 | M37: =IF(OR(K37="لم يدفع",B37=""),"",IFERROR(VLOOKUP(SUBSTITUTE(SUBSTITUTE(H37,"~","~~"),"*","~*"),إعدادات_الأنواع!$A$4:$E$40,5,FALSE()),0)) -> 500 | N37: =IF(OR(K37="لم يدفع",K37="تأمين فقط",K37="اشتراك 300",B37=""),"",IFERROR(VLOOKUP(SUBSTITUTE(SUBSTITUTE(H37,"~","~~"),"*","~*"),إعدادات_الأنواع!$A$4:$F$40,6,FALSE()),0)) -> 1000 | O37: =IF(K37="لم يدفع","",IF(L37="","",IF(N37="",L37+M37,L37+M37))) -> 2000 | P37: =IF(B37="","",IF(K37="لم يدفع","🔒 مجمدة",IF(J37="","",IF(J37<TODAY(),"⛔ منتهي - يتطلب تجديد",IF(J37-5<=TODAY(),"⚠️ قريب الانتهاء","✅ ساري"))))) -> ✅ ساري | Q37: الأحد والأربعاء | R37: 19:00-20:00 | S37: =IF(B37="","",COUNTA(التجديد!E37:E37)) -> 0 | T37: =IF(B37="","",IFERROR(VLOOKUP(SUBSTITUTE(SUBSTITUTE(H37,"~","~~"),"*","~*"),إعدادات_الأنواع!$A$4:$B$40,2,FALSE()),"?")) -> RCS
A38: =IF(B38="","",IF(T38="?","⚠️ نوع غير معرف",T38&TEXT(COUNTIFS($T$3:T38,T38),"000"))) -> RCS036 | B38: فلاح | C38: عبد الكريم | D38: 27915 | E38: ذكر | F38: =IF(D38="","",DATEDIF(D38,TODAY(),"Y")) -> 50 | H38: / | I38: 46194 | J38: =IF(I38="","",I38+30) -> 46224 | K38: مدفوع | L38: =IF(OR(K38="لم يدفع",B38=""),"",IF(K38="تأمين فقط",0,IF(K38="اشتراك 300",300,IF(F38<14,IFERROR(VLOOKUP(SUBSTITUTE(SUBSTITUTE(H38,"~","~~"),"*","~*"),إعدادات_الأنواع!$A$4:$D$40,3,FALSE()),0),IFERROR(VLOOKUP(SUBSTITUTE(SUBSTITUTE(H38,"~","~~"),"*","~*"),إعدادات_الأنواع!$A$4:$D$40,4,FALSE()),0))))) -> 1500 | M38: =IF(OR(K38="لم يدفع",B38=""),"",IFERROR(VLOOKUP(SUBSTITUTE(SUBSTITUTE(H38,"~","~~"),"*","~*"),إعدادات_الأنواع!$A$4:$E$40,5,FALSE()),0)) -> 500 | N38: =IF(OR(K38="لم يدفع",K38="تأمين فقط",K38="اشتراك 300",B38=""),"",IFERROR(VLOOKUP(SUBSTITUTE(SUBSTITUTE(H38,"~","~~"),"*","~*"),إعدادات_الأنواع!$A$4:$F$40,6,FALSE()),0)) -> 1000 | O38: =IF(K38="لم يدفع","",IF(L38="","",IF(N38="",L38+M38,L38+M38))) -> 2000 | P38: =IF(B38="","",IF(K38="لم يدفع","🔒 مجمدة",IF(J38="","",IF(J38<TODAY(),"⛔ منتهي - يتطلب تجديد",IF(J38-5<=TODAY(),"⚠️ قريب الانتهاء","✅ ساري"))))) -> ✅ ساري | Q38: الأحد والأربعاء | R38: 19:00-20:00 | S38: =IF(B38="","",COUNTA(التجديد!E38:E38)) -> 0 | T38: =IF(B38="","",IFERROR(VLOOKUP(SUBSTITUTE(SUBSTITUTE(H38,"~","~~"),"*","~*"),إعدادات_الأنواع!$A$4:$B$40,2,FALSE()),"?")) -> RCS
A39: =IF(B39="","",IF(T39="?","⚠️ نوع غير معرف",T39&TEXT(COUNTIFS($T$3:T39,T39),"000"))) -> RCS037 | B39: كروم | C39: عمر الفاروق | D39: 40822 | E39: ذكر | F39: =IF(D39="","",DATEDIF(D39,TODAY(),"Y")) -> 14 | H39: / | I39: 46194 | J39: =IF(I39="","",I39+30) -> 46224 | K39: مدفوع | L39: =IF(OR(K39="لم يدفع",B39=""),"",IF(K39="تأمين فقط",0,IF(K39="اشتراك 300",300,IF(F39<14,IFERROR(VLOOKUP(SUBSTITUTE(SUBSTITUTE(H39,"~","~~"),"*","~*"),إعدادات_الأنواع!$A$4:$D$40,3,FALSE()),0),IFERROR(VLOOKUP(SUBSTITUTE(SUBSTITUTE(H39,"~","~~"),"*","~*"),إعدادات_الأنواع!$A$4:$D$40,4,FALSE()),0))))) -> 1500 | M39: =IF(OR(K39="لم يدفع",B39=""),"",IFERROR(VLOOKUP(SUBSTITUTE(SUBSTITUTE(H39,"~","~~"),"*","~*"),إعدادات_الأنواع!$A$4:$E$40,5,FALSE()),0)) -> 500 | N39: =IF(OR(K39="لم يدفع",K39="تأمين فقط",K39="اشتراك 300",B39=""),"",IFERROR(VLOOKUP(SUBSTITUTE(SUBSTITUTE(H39,"~","~~"),"*","~*"),إعدادات_الأنواع!$A$4:$F$40,6,FALSE()),0)) -> 1000 | O39: =IF(K39="لم يدفع","",IF(L39="","",IF(N39="",L39+M39,L39+M39))) -> 2000 | P39: =IF(B39="","",IF(K39="لم يدفع","🔒 مجمدة",IF(J39="","",IF(J39<TODAY(),"⛔ منتهي - يتطلب تجديد",IF(J39-5<=TODAY(),"⚠️ قريب الانتهاء","✅ ساري"))))) -> ✅ ساري | Q39: الأحد والأربعاء | R39: 10:00-11:00 | S39: =IF(B39="","",COUNTA(التجديد!E39:E39)) -> 0 | T39: =IF(B39="","",IFERROR(VLOOKUP(SUBSTITUTE(SUBSTITUTE(H39,"~","~~"),"*","~*"),إعدادات_الأنواع!$A$4:$B$40,2,FALSE()),"?")) -> RCS
A40: =IF(B40="","",IF(T40="?","⚠️ نوع غير معرف",T40&TEXT(COUNTIFS($T$3:T40,T40),"000"))) -> RCS038 | B40: قاسمي | C40: صهيب | D40: 43725 | E40: ذكر | F40: =IF(D40="","",DATEDIF(D40,TODAY(),"Y")) -> 6 | H40: / | I40: 46197 | J40: =IF(I40="","",I40+30) -> 46227 | K40: مدفوع | L40: =IF(OR(K40="لم يدفع",B40=""),"",IF(K40="تأمين فقط",0,IF(K40="اشتراك 300",300,IF(F40<14,IFERROR(VLOOKUP(SUBSTITUTE(SUBSTITUTE(H40,"~","~~"),"*","~*"),إعدادات_الأنواع!$A$4:$D$40,3,FALSE()),0),IFERROR(VLOOKUP(SUBSTITUTE(SUBSTITUTE(H40,"~","~~"),"*","~*"),إعدادات_الأنواع!$A$4:$D$40,4,FALSE()),0))))) -> 1300 | M40: =IF(OR(K40="لم يدفع",B40=""),"",IFERROR(VLOOKUP(SUBSTITUTE(SUBSTITUTE(H40,"~","~~"),"*","~*"),إعدادات_الأنواع!$A$4:$E$40,5,FALSE()),0)) -> 500 | N40: =IF(OR(K40="لم يدفع",K40="تأمين فقط",K40="اشتراك 300",B40=""),"",IFERROR(VLOOKUP(SUBSTITUTE(SUBSTITUTE(H40,"~","~~"),"*","~*"),إعدادات_الأنواع!$A$4:$F$40,6,FALSE()),0)) -> 1000 | O40: =IF(K40="لم يدفع","",IF(L40="","",IF(N40="",L40+M40,L40+M40))) -> 1800 | P40: =IF(B40="","",IF(K40="لم يدفع","🔒 مجمدة",IF(J40="","",IF(J40<TODAY(),"⛔ منتهي - يتطلب تجديد",IF(J40-5<=TODAY(),"⚠️ قريب الانتهاء","✅ ساري"))))) -> ✅ ساري | Q40: الأحد والأربعاء | R40: 10:00-11:00 | S40: =IF(B40="","",COUNTA(التجديد!E40:E40)) -> 0 | T40: =IF(B40="","",IFERROR(VLOOKUP(SUBSTITUTE(SUBSTITUTE(H40,"~","~~"),"*","~*"),إعدادات_الأنواع!$A$4:$B$40,2,FALSE()),"?")) -> RCS
...

Sheet إعدادات_الأنواع
A1: ⚙️ إعدادات أنواع الاشتراك — نادي RCS
A2: لإضافة نوع اشتراك جديد: أضف سطراً جديداً أسفل الجدول بنفس الأعمدة — سيعمل تلقائياً في كل الملف (الترقيم + الرسوم) دون أي تعديل على الصيغ.
A3: كود النوع (كما يُكتب في H) | B3: البادئة (Prefix) | C3: رسوم الاشتراك (تحت 14 سنة) | D3: رسوم الاشتراك (14 سنة فأكثر) | E3: رسوم التأمين | F3: حقوق المركب | G3: ملاحظات
A4: / | B4: RCS | C4: 1300 | D4: 1500 | E4: 500 | F4: 1000 | G4: اشتراك عادي
A5: DJS | B5: RCS | C5: 300 | D5: 500 | E5: 500 | F5: 0 | G5: الاشتراك و التأمين فقط
A6: POLICE | B6: RCS | C6: 300 | D6: 300 | E6: 500 | F6: 0 | G6: الاشتراك و التأمين فقط
A7: MJ | B7: RCS | C7: 0 | D7: 0 | E7: 0 | F7: 0 | G7: معفى استثنائيًا من رسوم الاشتراك والتأمين
A8: ** | B8: X | C8: 0 | D8: 0 | E8: 0 | F8: 0 | G8: معفى من جميع الرسوم

Sheet حقوق_المركب
A1: 🏊 سجل حقوق المركب — نادي RCS
A2: اللقب | B2: الاسم | C2: المبلغ
A3: =IF(بيانات!N3=1000,بيانات!B3,"") -> بورقعة | B3: =IF(بيانات!N3=1000,بيانات!C3,"") -> محمد الأمين | C3: =IF(بيانات!N3=1000,1000,"") -> 1000
A4: =IF(بيانات!N4=1000,بيانات!B4,"") -> براهمي | B4: =IF(بيانات!N4=1000,بيانات!C4,"") -> ياسين صلاح الدين | C4: =IF(بيانات!N4=1000,1000,"") -> 1000
A5: =IF(بيانات!N5=1000,بيانات!B5,"") -> براهمي | B5: =IF(بيانات!N5=1000,بيانات!C5,"") -> فؤاد عبد القادر | C5: =IF(بيانات!N5=1000,1000,"") -> 1000
A6: =IF(بيانات!N6=1000,بيانات!B6,"") -> يحياوي | B6: =IF(بيانات!N6=1000,بيانات!C6,"") -> عز الدين عبد القادر | C6: =IF(بيانات!N6=1000,1000,"") -> 1000
A7: =IF(بيانات!N7=1000,بيانات!B7,"") | B7: =IF(بيانات!N7=1000,بيانات!C7,"") | C7: =IF(بيانات!N7=1000,1000,"")
A8: =IF(بيانات!N8=1000,بيانات!B8,"") | B8: =IF(بيانات!N8=1000,بيانات!C8,"") | C8: =IF(بيانات!N8=1000,1000,"")
A9: =IF(بيانات!N9=1000,بيانات!B9,"") | B9: =IF(بيانات!N9=1000,بيانات!C9,"") | C9: =IF(بيانات!N9=1000,1000,"")
A10: =IF(بيانات!N10=1000,بيانات!B10,"") | B10: =IF(بيانات!N10=1000,بيانات!C10,"") | C10: =IF(بيانات!N10=1000,1000,"")
A11: =IF(بيانات!N11=1000,بيانات!B11,"") -> علام | B11: =IF(بيانات!N11=1000,بيانات!C11,"") -> محمد | C11: =IF(بيانات!N11=1000,1000,"") -> 1000
A12: =IF(بيانات!N12=1000,بيانات!B12,"") -> علو | B12: =IF(بيانات!N12=1000,بيانات!C12,"") -> ادم ضياء الدين | C12: =IF(بيانات!N12=1000,1000,"") -> 1000
A13: =IF(بيانات!N13=1000,بيانات!B13,"") -> بغاديد | B13: =IF(بيانات!N13=1000,بيانات!C13,"") -> احمد عماد الدين | C13: =IF(بيانات!N13=1000,1000,"") -> 1000
A14: =IF(بيانات!N14=1000,بيانات!B14,"") -> هواري | B14: =IF(بيانات!N14=1000,بيانات!C14,"") -> عماد ايمن | C14: =IF(بيانات!N14=1000,1000,"") -> 1000
... A3176: =IF(بيانات!N3176=1000,بيانات!B3176,"") | B3176: =IF(بيانات!N3176=1000,بيانات!C3176,"") | C3176: =IF(بيانات!N3176=1000,1000,"")
A3178: 📊 الإجماليات
A3179: عدد المنخرطين المعنيين | C3179: =COUNTIF(بيانات!N3:N3176,1000)&" منخرط" -> 171 منخرط
A3180: 📈 ملخص إحصائي
A3181: عدد المشتركين برسوم 1300 دج | C3181: =COUNTIFS(بيانات!N3:N3176,1000,بيانات!L3:L3176,1300)&" منخرط" -> 100 منخرط
A3182: عدد المشتركين برسوم 1500 دج | C3182: =COUNTIFS(بيانات!N3:N3176,1000,بيانات!L3:L3176,1500)&" منخرط" -> 71 منخرط
A3183: إجمالي حقوق المركب المحصلة | C3183: =(COUNTIF(بيانات!N3:N3176,1000)*1000)&" دج" -> 171000 دج
A3184: إجمالي رسوم الاشتراك (لهؤلاء) | C3184: =SUMIF(بيانات!N3:N3176,1000,بيانات!L3:L3176)&" دج" -> 236500 دج
A3185: إجمالي المبالغ الكلية (لهؤلاء) | C3185: =SUMIF(بيانات!N3:N3176,1000,بيانات!O3:O3176)&" دج" -> 322000 دج
A3187: ✦ نادي RCS | سجل حقوق المركب | يتحدث تلقائياً مع ورقة البيانات ✦

Sheet قائمة_التأمين
A1: 🛡️ قائمة التأمين — نادي RCS | F1: 📊 ملخص التغطية التأمينية
A2: اللقب | B2: الاسم | C2: تاريخ الميلاد | D2: الحالة التأمينية | F2: إجمالي المنخرطين المسجلين | G2: =COUNTA(بيانات!B3:B3176) -> 199
A3: =IF(بيانات!B3<>"",بيانات!B3,"") -> بورقعة | B3: =IF(بيانات!B3<>"",بيانات!C3,"") -> محمد الأمين | C3: =IF(بيانات!B3<>"",بيانات!D3,"") -> 41766 | D3: مؤمن | F3: ✅ عدد المؤمنين | G3: =COUNTIF(D3:D3176,"مؤمن") -> 34
A4: =IF(بيانات!B4<>"",بيانات!B4,"") -> براهمي | B4: =IF(بيانات!B4<>"",بيانات!C4,"") -> ياسين صلاح الدين | C4: =IF(بيانات!B4<>"",بيانات!D4,"") -> 41925 | D4: مؤمن | F4: ⚠️ عدد غير المؤمنين | G4: =COUNTIF(D3:D3176,"غير مؤمن") -> 0
A5: =IF(بيانات!B5<>"",بيانات!B5,"") -> براهمي | B5: =IF(بيانات!B5<>"",بيانات!C5,"") -> فؤاد عبد القادر | C5: =IF(بيانات!B5<>"",بيانات!D5,"") -> 40915 | D5: مؤمن | F5: ❔ لم تُحدَّد حالتهم بعد | G5: =COUNTA(بيانات!B3:B3176)-COUNTIF(D3:D3176,"مؤمن")-COUNTIF(D3:D3176,"غير مؤمن") -> 165
A6: =IF(بيانات!B6<>"",بيانات!B6,"") -> يحياوي | B6: =IF(بيانات!B6<>"",بيانات!C6,"") -> عز الدين عبد القادر | C6: =IF(بيانات!B6<>"",بيانات!D6,"") -> 42864 | D6: مؤمن
A7: =IF(بيانات!B7<>"",بيانات!B7,"") -> غزالي | B7: =IF(بيانات!B7<>"",بيانات!C7,"") -> ياسر | C7: =IF(بيانات!B7<>"",بيانات!D7,"") -> 42727 | D7: مؤمن
A8: =IF(بيانات!B8<>"",بيانات!B8,"") -> غزالي | B8: =IF(بيانات!B8<>"",بيانات!C8,"") -> آية | C8: =IF(بيانات!B8<>"",بيانات!D8,"") -> 43275 | D8: مؤمن
A9: =IF(بيانات!B9<>"",بيانات!B9,"") -> علو | B9: =IF(بيانات!B9<>"",بيانات!C9,"") -> عبد الإله | C9: =IF(بيانات!B9<>"",بيانات!D9,"") -> 41323 | D9: مؤمن
A10: =IF(بيانات!B10<>"",بيانات!B10,"") -> علو | B10: =IF(بيانات!B10<>"",بيانات!C10,"") -> صهيب | C10: =IF(بيانات!B10<>"",بيانات!D10,"") -> 43273 | D10: مؤمن
A11: =IF(بيانات!B11<>"",بيانات!B11,"") -> علام | B11: =IF(بيانات!B11<>"",بيانات!C11,"") -> محمد | C11: =IF(بيانات!B11<>"",بيانات!D11,"") -> 42326 | D11: مؤمن
A12: =IF(بيانات!B12<>"",بيانات!B12,"") -> علو | B12: =IF(بيانات!B12<>"",بيانات!C12,"") -> ادم ضياء الدين | C12: =IF(بيانات!B12<>"",بيانات!D12,"") -> 41123 | D12: مؤمن
A13: =IF(بيانات!B13<>"",بيانات!B13,"") -> بغاديد | B13: =IF(بيانات!B13<>"",بيانات!C13,"") -> احمد عماد الدين | C13: =IF(بيانات!B13<>"",بيانات!D13,"") -> 41578 | D13: مؤمن
A14: =IF(بيانات!B14<>"",بيانات!B14,"") -> هواري | B14: =IF(بيانات!B14<>"",بيانات!C14,"") -> عماد ايمن | C14: =IF(بيانات!B14<>"",بيانات!D14,"") -> 42242 | D14: مؤمن
A15: =IF(بيانات!B15<>"",بيانات!B15,"") -> بن | B15: =IF(بيانات!B15<>"",بيانات!C15,"") -> حشيليف رنيم سجود | C15: =IF(بيانات!B15<>"",بيانات!D15,"") -> 44220 | D15: مؤمن
A16: =IF(بيانات!B16<>"",بيانات!B16,"") -> قدو شريف | B16: =IF(بيانات!B16<>"",بيانات!C16,"") -> صفاء سلسبيل | C16: =IF(بيانات!B16<>"",بيانات!D16,"") -> 43285 | D16: مؤمن
A17: =IF(بيانات!B17<>"",بيانات!B17,"") -> قدو شريف | B17: =IF(بيانات!B17<>"",بيانات!C17,"") -> ثراء كوثر | C17: =IF(بيانات!B17<>"",بيانات!D17,"") -> 42925 | D17: مؤمن
... A36: =IF(بيانات!B36<>"",بيانات!B36,"") -> جرفي | B36: =IF(بيانات!B36<>"",بيانات!C36,"") -> حسين | C36: =IF(بيانات!B36<>"",بيانات!D36,"") -> 38830 | D36: مؤمن
A37: =IF(بيانات!B37<>"",بيانات!B37,"") -> راي | B37: =IF(بيانات!B37<>"",بيانات!C37,"") -> أحمد الجيلالي | C37: =IF(بيانات!B37<>"",بيانات!D37,"") -> 33975
A38: =IF(بيانات!B38<>"",بيانات!B38,"") -> فلاح | B38: =IF(بيانات!B38<>"",بيانات!C38,"") -> عبد الكريم | C38: =IF(بيانات!B38<>"",بيانات!D38,"") -> 27915
A39: =IF(بيانات!B39<>"",بيانات!B39,"") -> كروم | B39: =IF(بيانات!B39<>"",بيانات!C39,"") -> عمر الفاروق | C39: =IF(بيانات!B39<>"",بيانات!D39,"") -> 40822
